exchange,symbol,timestamp,local_timestamp,is_snapshot,side,price,amount
binance,BTCUSDT,1575158405045139,1575158405045139,true,ask,7541.38,0.085806
binance,BTCUSDT,1575158405045139,1575158405045139,true,ask,7541.39,0.013013
binance,BTCUSDT,1575158405045139,1575158405045139,true,ask,7541.4,4
binance,BTCUSDT,1575158405045139,1575158405045139,true,ask,7541.44,5.045272
binance,BTCUSDT,1575158405045139,1575158405045139,true,ask,7541.45,3.995438
binance,BTCUSDT,1575158405045139,1575158405045139,true,ask,7541.46,1.971371
binance,BTCUSDT,1575158405045139,1575158405045139,true,ask,7541.47,4
binance,BTCUSDT,1575158405045139,1575158405045139,true,ask,7541.48,0.097294
binance,BTCUSDT,1575158405045139,1575158405045139,true,ask,7541.49,0.3
binance,BTCUSDT,1575158405045139,1575158405045139,true,ask,7541.5,0.082835
binance,BTCUSDT,1575158405045139,1575158405045139,true,ask,7541.85,0.444445
binance,BTCUSDT,1575158405045139,1575158405045139,true,ask,7541.87,0.118029
binance,BTCUSDT,1575158405045139,1575158405045139,true,ask,7541.9,0.007333
binance,BTCUSDT,1575158405045139,1575158405045139,true,ask,7541.91,0.212169
binance,BTCUSDT,1575158405045139,1575158405045139,true,ask,7541.92,3.112586
binance,BTCUSDT,1575158405045139,1575158405045139,true,ask,7541.93,0.067456
binance,BTCUSDT,1575158405045139,1575158405045139,true,ask,7542.5,0.8757
binance,BTCUSDT,1575158405045139,1575158405045139,true,ask,7542.85,0.5
binance,BTCUSDT,1575158405045139,1575158405045139,true,ask,7543.15,0.110091
binance,BTCUSDT,1575158405045139,1575158405045139,true,ask,7543.16,0.397866
binance,BTCUSDT,1575158405045139,1575158405045139,true,ask,7543.18,0.083633
binance,BTCUSDT,1575158405045139,1575158405045139,true,ask,7543.19,2
binance,BTCUSDT,1575158405045139,1575158405045139,true,ask,7543.23,0.210965
binance,BTCUSDT,1575158405045139,1575158405045139,true,ask,7543.44,0.5
binance,BTCUSDT,1575158405045139,1575158405045139,true,ask,7543.8,0.5
binance,BTCUSDT,1575158405045139,1575158405045139,true,ask,7544.42,0.09921
binance,BTCUSDT,1575158405045139,1575158405045139,true,ask,7544.43,1.154868
binance,BTCUSDT,1575158405045139,1575158405045139,true,ask,7544.44,2
binance,BTCUSDT,1575158405045139,1575158405045139,true,ask,7544.68,2
binance,BTCUSDT,1575158405045139,1575158405045139,true,ask,7545,0.5
binance,BTCUSDT,1575158405045139,1575158405045139,true,ask,7545.17,0.065067
binance,BTCUSDT,1575158405045139,1575158405045139,true,ask,7545.63,6
binance,BTCUSDT,1575158405045139,1575158405045139,true,ask,7545.66,0.01009
binance,BTCUSDT,1575158405045139,1575158405045139,true,ask,7545.87,1.025639
binance,BTCUSDT,1575158405045139,1575158405045139,true,ask,7546.16,0.5
binance,BTCUSDT,1575158405045139,1575158405045139,true,ask,7546.53,0.3
binance,BTCUSDT,1575158405045139,1575158405045139,true,ask,7546.64,2.82
binance,BTCUSDT,1575158405045139,1575158405045139,true,ask,7546.69,0.091885
binance,BTCUSDT,1575158405045139,1575158405045139,true,ask,7546.73,1.15999
binance,BTCUSDT,1575158405045139,1575158405045139,true,ask,7547.18,0.033125
binance,BTCUSDT,1575158405045139,1575158405045139,true,ask,7547.19,0.00974
binance,BTCUSDT,1575158405045139,1575158405045139,true,ask,7547.74,0.036185
binance,BTCUSDT,1575158405045139,1575158405045139,true,ask,7547.92,0.182145
binance,BTCUSDT,1575158405045139,1575158405045139,true,ask,7547.99,0.477303
binance,BTCUSDT,1575158405045139,1575158405045139,true,ask,7548.22,0.030412
binance,BTCUSDT,1575158405045139,1575158405045139,true,ask,7548.46,0.5
binance,BTCUSDT,1575158405045139,1575158405045139,true,ask,7548.53,0.271389
binance,BTCUSDT,1575158405045139,1575158405045139,true,ask,7548.83,0.01033
binance,BTCUSDT,1575158405045139,1575158405045139,true,ask,7548.86,0.05
binance,BTCUSDT,1575158405045139,1575158405045139,true,ask,7548.89,0.092073
binance,BTCUSDT,1575158405045139,1575158405045139,true,ask,7548.9,0.291782
binance,BTCUSDT,1575158405045139,1575158405045139,true,ask,7548.94,0.24
binance,BTCUSDT,1575158405045139,1575158405045139,true,ask,7549.06,2
binance,BTCUSDT,1575158405045139,1575158405045139,true,ask,7549.66,0.929669
binance,BTCUSDT,1575158405045139,1575158405045139,true,ask,7549.91,0.1
binance,BTCUSDT,1575158405045139,1575158405045139,true,ask,7550.08,0.056676
binance,BTCUSDT,1575158405045139,1575158405045139,true,ask,7550.09,2
binance,BTCUSDT,1575158405045139,1575158405045139,true,ask,7550.1,0.0054
binance,BTCUSDT,1575158405045139,1575158405045139,true,ask,7550.28,0.003814
binance,BTCUSDT,1575158405045139,1575158405045139,true,ask,7550.52,2.1
binance,BTCUSDT,1575158405045139,1575158405045139,true,ask,7550.68,2.317
binance,BTCUSDT,1575158405045139,1575158405045139,true,ask,7550.71,0.13333
binance,BTCUSDT,1575158405045139,1575158405045139,true,ask,7550.79,0.5
binance,BTCUSDT,1575158405045139,1575158405045139,true,ask,7550.93,2.1
binance,BTCUSDT,1575158405045139,1575158405045139,true,ask,7550.95,2.1
binance,BTCUSDT,1575158405045139,1575158405045139,true,ask,7550.99,2.096552
binance,BTCUSDT,1575158405045139,1575158405045139,true,ask,7551.02,0.042827
binance,BTCUSDT,1575158405045139,1575158405045139,true,ask,7551.22,0.01712
binance,BTCUSDT,1575158405045139,1575158405045139,true,ask,7551.31,0.001336
binance,BTCUSDT,1575158405045139,1575158405045139,true,ask,7551.34,1.732359
binance,BTCUSDT,1575158405045139,1575158405045139,true,ask,7551.38,0.397301
binance,BTCUSDT,1575158405045139,1575158405045139,true,ask,7551.56,0.003814
binance,BTCUSDT,1575158405045139,1575158405045139,true,ask,7551.86,1.97956
binance,BTCUSDT,1575158405045139,1575158405045139,true,ask,7552,3.573662
binance,BTCUSDT,1575158405045139,1575158405045139,true,ask,7552.01,0.005
binance,BTCUSDT,1575158405045139,1575158405045139,true,ask,7552.5,0.063954
binance,BTCUSDT,1575158405045139,1575158405045139,true,ask,7552.6,0.001336
binance,BTCUSDT,1575158405045139,1575158405045139,true,ask,7552.81,0.3
binance,BTCUSDT,1575158405045139,1575158405045139,true,ask,7552.84,0.003814
binance,BTCUSDT,1575158405045139,1575158405045139,true,ask,7552.89,0.397207
binance,BTCUSDT,1575158405045139,1575158405045139,true,ask,7553.19,29.117681
binance,BTCUSDT,1575158405045139,1575158405045139,true,ask,7553.32,12
binance,BTCUSDT,1575158405045139,1575158405045139,true,ask,7553.5,2.1
binance,BTCUSDT,1575158405045139,1575158405045139,true,ask,7553.58,2.1
binance,BTCUSDT,1575158405045139,1575158405045139,true,ask,7553.61,0.1
binance,BTCUSDT,1575158405045139,1575158405045139,true,ask,7554.02,0.004098
binance,BTCUSDT,1575158405045139,1575158405045139,true,ask,7554.12,0.003814
binance,BTCUSDT,1575158405045139,1575158405045139,true,ask,7554.41,0.397135
binance,BTCUSDT,1575158405045139,1575158405045139,true,ask,7554.56,0.002136
binance,BTCUSDT,1575158405045139,1575158405045139,true,ask,7555.25,1.605
binance,BTCUSDT,1575158405045139,1575158405045139,true,ask,7555.4,0.003814
binance,BTCUSDT,1575158405045139,1575158405045139,true,ask,7555.73,0.00935
binance,BTCUSDT,1575158405045139,1575158405045139,true,ask,7555.93,0.397062
binance,BTCUSDT,1575158405045139,1575158405045139,true,ask,7556,0.011856
binance,BTCUSDT,1575158405045139,1575158405045139,true,ask,7556.39,0.473961
binance,BTCUSDT,1575158405045139,1575158405045139,true,ask,7556.4,2
binance,BTCUSDT,1575158405045139,1575158405045139,true,ask,7556.68,0.003814
binance,BTCUSDT,1575158405045139,1575158405045139,true,ask,7556.96,0.00224
binance,BTCUSDT,1575158405045139,1575158405045139,true,ask,7557,0.321288
binance,BTCUSDT,1575158405045139,1575158405045139,true,ask,7557.2,2
binance,BTCUSDT,1575158405045139,1575158405045139,true,ask,7557.25,2
binance,BTCUSDT,1575158405045139,1575158405045139,true,ask,7557.34,2
binance,BTCUSDT,1575158405045139,1575158405045139,true,ask,7557.44,0.397029
binance,BTCUSDT,1575158405045139,1575158405045139,true,ask,7557.96,0.003814
binance,BTCUSDT,1575158405045139,1575158405045139,true,ask,7557.99,0.006624
binance,BTCUSDT,1575158405045139,1575158405045139,true,ask,7558.04,0.010603
binance,BTCUSDT,1575158405045139,1575158405045139,true,ask,7558.46,0.019425
binance,BTCUSDT,1575158405045139,1575158405045139,true,ask,7558.5,2
binance,BTCUSDT,1575158405045139,1575158405045139,true,ask,7558.57,2
binance,BTCUSDT,1575158405045139,1575158405045139,true,ask,7558.8,0.001591
binance,BTCUSDT,1575158405045139,1575158405045139,true,ask,7558.96,0.396907
binance,BTCUSDT,1575158405045139,1575158405045139,true,ask,7559,37.183502
binance,BTCUSDT,1575158405045139,1575158405045139,true,ask,7559.02,0.06159
binance,BTCUSDT,1575158405045139,1575158405045139,true,ask,7559.24,0.003814
binance,BTCUSDT,1575158405045139,1575158405045139,true,ask,7559.41,0.038858
binance,BTCUSDT,1575158405045139,1575158405045139,true,ask,7559.45,0.5
binance,BTCUSDT,1575158405045139,1575158405045139,true,ask,7559.89,0.250676
binance,BTCUSDT,1575158405045139,1575158405045139,true,ask,7559.95,1.539
binance,BTCUSDT,1575158405045139,1575158405045139,true,ask,7560,5.477788
binance,BTCUSDT,1575158405045139,1575158405045139,true,ask,7560.18,0.030364
binance,BTCUSDT,1575158405045139,1575158405045139,true,ask,7560.31,0.947932
binance,BTCUSDT,1575158405045139,1575158405045139,true,ask,7560.36,0.035864
binance,BTCUSDT,1575158405045139,1575158405045139,true,ask,7560.4,0.01046
binance,BTCUSDT,1575158405045139,1575158405045139,true,ask,7560.42,0.002666
binance,BTCUSDT,1575158405045139,1575158405045139,true,ask,7560.45,0.362744
binance,BTCUSDT,1575158405045139,1575158405045139,true,ask,7560.48,0.396907
binance,BTCUSDT,1575158405045139,1575158405045139,true,ask,7560.51,0.047695
binance,BTCUSDT,1575158405045139,1575158405045139,true,ask,7560.52,0.003814
binance,BTCUSDT,1575158405045139,1575158405045139,true,ask,7560.61,0.0025
binance,BTCUSDT,1575158405045139,1575158405045139,true,ask,7560.89,3.954903
binance,BTCUSDT,1575158405045139,1575158405045139,true,ask,7561.07,0.002665
binance,BTCUSDT,1575158405045139,1575158405045139,true,ask,7561.4,0.004
binance,BTCUSDT,1575158405045139,1575158405045139,true,ask,7561.8,0.003814
binance,BTCUSDT,1575158405045139,1575158405045139,true,ask,7561.99,0.396739
binance,BTCUSDT,1575158405045139,1575158405045139,true,ask,7562.17,0.002665
binance,BTCUSDT,1575158405045139,1575158405045139,true,ask,7562.28,0.001993
binance,BTCUSDT,1575158405045139,1575158405045139,true,ask,7562.33,0.001993
binance,BTCUSDT,1575158405045139,1575158405045139,true,ask,7562.35,0.001459
binance,BTCUSDT,1575158405045139,1575158405045139,true,ask,7562.49,0.001995
binance,BTCUSDT,1575158405045139,1575158405045139,true,ask,7562.62,0.1
binance,BTCUSDT,1575158405045139,1575158405045139,true,ask,7562.86,0.005769
binance,BTCUSDT,1575158405045139,1575158405045139,true,ask,7562.9,0.001993
binance,BTCUSDT,1575158405045139,1575158405045139,true,ask,7562.97,0.002665
binance,BTCUSDT,1575158405045139,1575158405045139,true,ask,7563,45.01
binance,BTCUSDT,1575158405045139,1575158405045139,true,ask,7563.05,0.806018
binance,BTCUSDT,1575158405045139,1575158405045139,true,ask,7563.08,0.005807
binance,BTCUSDT,1575158405045139,1575158405045139,true,ask,7563.11,0.002665
binance,BTCUSDT,1575158405045139,1575158405045139,true,ask,7563.29,0.040149
binance,BTCUSDT,1575158405045139,1575158405045139,true,ask,7563.48,0.00399
binance,BTCUSDT,1575158405045139,1575158405045139,true,ask,7563.51,0.49934
binance,BTCUSDT,1575158405045139,1575158405045139,true,ask,7563.6,2
binance,BTCUSDT,1575158405045139,1575158405045139,true,ask,7563.63,0.1
binance,BTCUSDT,1575158405045139,1575158405045139,true,ask,7563.66,0.034222
binance,BTCUSDT,1575158405045139,1575158405045139,true,ask,7563.69,0.00399
binance,BTCUSDT,1575158405045139,1575158405045139,true,ask,7563.99,0.048675
binance,BTCUSDT,1575158405045139,1575158405045139,true,ask,7564.1,0.009709
binance,BTCUSDT,1575158405045139,1575158405045139,true,ask,7564.13,0.001323
binance,BTCUSDT,1575158405045139,1575158405045139,true,ask,7564.15,0.001993
binance,BTCUSDT,1575158405045139,1575158405045139,true,ask,7564.16,0.093029
binance,BTCUSDT,1575158405045139,1575158405045139,true,ask,7564.17,0.058268
binance,BTCUSDT,1575158405045139,1575158405045139,true,ask,7564.19,0.053035
binance,BTCUSDT,1575158405045139,1575158405045139,true,ask,7564.24,0.002236
binance,BTCUSDT,1575158405045139,1575158405045139,true,ask,7564.29,0.001993
binance,BTCUSDT,1575158405045139,1575158405045139,true,ask,7564.36,0.012659
binance,BTCUSDT,1575158405045139,1575158405045139,true,ask,7564.53,0.001993
binance,BTCUSDT,1575158405045139,1575158405045139,true,ask,7564.61,0.001993
binance,BTCUSDT,1575158405045139,1575158405045139,true,ask,7564.67,0.012088
binance,BTCUSDT,1575158405045139,1575158405045139,true,ask,7564.71,0.0015
binance,BTCUSDT,1575158405045139,1575158405045139,true,ask,7564.8,0.003989
binance,BTCUSDT,1575158405045139,1575158405045139,true,ask,7564.93,0.016116
binance,BTCUSDT,1575158405045139,1575158405045139,true,ask,7564.94,0.034392
binance,BTCUSDT,1575158405045139,1575158405045139,true,ask,7565,7.729808
binance,BTCUSDT,1575158405045139,1575158405045139,true,ask,7565.21,0.002974
binance,BTCUSDT,1575158405045139,1575158405045139,true,ask,7565.24,0.001993
binance,BTCUSDT,1575158405045139,1575158405045139,true,ask,7565.27,0.00745
binance,BTCUSDT,1575158405045139,1575158405045139,true,ask,7565.45,0.003888
binance,BTCUSDT,1575158405045139,1575158405045139,true,ask,7565.55,0.012071
binance,BTCUSDT,1575158405045139,1575158405045139,true,ask,7565.62,0.02572
binance,BTCUSDT,1575158405045139,1575158405045139,true,ask,7565.64,0.003814
binance,BTCUSDT,1575158405045139,1575158405045139,true,ask,7565.8,0.25
binance,BTCUSDT,1575158405045139,1575158405045139,true,ask,7565.92,0.019925
binance,BTCUSDT,1575158405045139,1575158405045139,true,ask,7565.95,0.002259
binance,BTCUSDT,1575158405045139,1575158405045139,true,ask,7566.03,9.361602
binance,BTCUSDT,1575158405045139,1575158405045139,true,ask,7566.1,0.003989
binance,BTCUSDT,1575158405045139,1575158405045139,true,ask,7566.14,0.001992
binance,BTCUSDT,1575158405045139,1575158405045139,true,ask,7566.28,0.045599
binance,BTCUSDT,1575158405045139,1575158405045139,true,ask,7566.32,0.042827
binance,BTCUSDT,1575158405045139,1575158405045139,true,ask,7566.43,0.007547
binance,BTCUSDT,1575158405045139,1575158405045139,true,ask,7566.47,0.020263
binance,BTCUSDT,1575158405045139,1575158405045139,true,ask,7566.48,0.004893
binance,BTCUSDT,1575158405045139,1575158405045139,true,ask,7566.5,0.001992
binance,BTCUSDT,1575158405045139,1575158405045139,true,ask,7566.66,0.014624
binance,BTCUSDT,1575158405045139,1575158405045139,true,ask,7566.73,0.068717
binance,BTCUSDT,1575158405045139,1575158405045139,true,ask,7566.74,0.007132
binance,BTCUSDT,1575158405045139,1575158405045139,true,ask,7566.76,0.002663
binance,BTCUSDT,1575158405045139,1575158405045139,true,ask,7566.92,0.006477
binance,BTCUSDT,1575158405045139,1575158405045139,true,ask,7567.03,0.016854
binance,BTCUSDT,1575158405045139,1575158405045139,true,ask,7567.2,0.25
binance,BTCUSDT,1575158405045139,1575158405045139,true,ask,7567.37,0.028931
binance,BTCUSDT,1575158405045139,1575158405045139,true,ask,7567.4,0.001992
binance,BTCUSDT,1575158405045139,1575158405045139,true,ask,7567.5,1.95
binance,BTCUSDT,1575158405045139,1575158405045139,true,ask,7567.58,0.064282
binance,BTCUSDT,1575158405045139,1575158405045139,true,ask,7568,0.02
binance,BTCUSDT,1575158405045139,1575158405045139,true,ask,7568.08,0.198906
binance,BTCUSDT,1575158405045139,1575158405045139,true,ask,7568.29,0.8
binance,BTCUSDT,1575158405045139,1575158405045139,true,ask,7568.3,0.002708
binance,BTCUSDT,1575158405045139,1575158405045139,true,ask,7568.43,0.001992
binance,BTCUSDT,1575158405045139,1575158405045139,true,ask,7568.49,0.02
binance,BTCUSDT,1575158405045139,1575158405045139,true,ask,7568.68,0.004512
binance,BTCUSDT,1575158405045139,1575158405045139,true,ask,7568.7,0.317787
binance,BTCUSDT,1575158405045139,1575158405045139,true,ask,7568.88,0.05
binance,BTCUSDT,1575158405045139,1575158405045139,true,ask,7568.9,0.003984
binance,BTCUSDT,1575158405045139,1575158405045139,true,ask,7568.91,0.001992
binance,BTCUSDT,1575158405045139,1575158405045139,true,ask,7568.92,0.001891
binance,BTCUSDT,1575158405045139,1575158405045139,true,ask,7569,45.01273
binance,BTCUSDT,1575158405045139,1575158405045139,true,ask,7569.23,0.3027
binance,BTCUSDT,1575158405045139,1575158405045139,true,ask,7569.27,0.001657
binance,BTCUSDT,1575158405045139,1575158405045139,true,ask,7569.5,0.001637
binance,BTCUSDT,1575158405045139,1575158405045139,true,ask,7569.55,0.058596
binance,BTCUSDT,1575158405045139,1575158405045139,true,ask,7569.59,0.004163
binance,BTCUSDT,1575158405045139,1575158405045139,true,ask,7569.62,0.025323
binance,BTCUSDT,1575158405045139,1575158405045139,true,ask,7569.67,0.001992
binance,BTCUSDT,1575158405045139,1575158405045139,true,ask,7569.8,0.001991
binance,BTCUSDT,1575158405045139,1575158405045139,true,ask,7569.86,0.005804
binance,BTCUSDT,1575158405045139,1575158405045139,true,ask,7570,8.187626
binance,BTCUSDT,1575158405045139,1575158405045139,true,ask,7570.03,0.016303
binance,BTCUSDT,1575158405045139,1575158405045139,true,ask,7570.2,0.8328
binance,BTCUSDT,1575158405045139,1575158405045139,true,ask,7570.22,0.001411
binance,BTCUSDT,1575158405045139,1575158405045139,true,ask,7570.29,0.5
binance,BTCUSDT,1575158405045139,1575158405045139,true,ask,7570.45,1.421951
binance,BTCUSDT,1575158405045139,1575158405045139,true,ask,7570.56,0.4188
binance,BTCUSDT,1575158405045139,1575158405045139,true,ask,7570.65,0.001991
binance,BTCUSDT,1575158405045139,1575158405045139,true,ask,7570.77,1.500054
binance,BTCUSDT,1575158405045139,1575158405045139,true,ask,7570.86,0.002662
binance,BTCUSDT,1575158405045139,1575158405045139,true,ask,7570.93,0.002662
binance,BTCUSDT,1575158405045139,1575158405045139,true,ask,7570.94,0.001991
binance,BTCUSDT,1575158405045139,1575158405045139,true,ask,7570.98,0.026417
binance,BTCUSDT,1575158405045139,1575158405045139,true,ask,7571.11,0.112333
binance,BTCUSDT,1575158405045139,1575158405045139,true,ask,7571.14,0.112333
binance,BTCUSDT,1575158405045139,1575158405045139,true,ask,7571.16,0.159558
binance,BTCUSDT,1575158405045139,1575158405045139,true,ask,7571.18,0.009914
binance,BTCUSDT,1575158405045139,1575158405045139,true,ask,7571.21,0.202184
binance,BTCUSDT,1575158405045139,1575158405045139,true,ask,7571.22,0.061709
binance,BTCUSDT,1575158405045139,1575158405045139,true,ask,7571.26,0.053741
binance,BTCUSDT,1575158405045139,1575158405045139,true,ask,7571.37,0.00199
binance,BTCUSDT,1575158405045139,1575158405045139,true,ask,7571.38,0.2
binance,BTCUSDT,1575158405045139,1575158405045139,true,ask,7571.42,0.001486
binance,BTCUSDT,1575158405045139,1575158405045139,true,ask,7571.43,0.053741
binance,BTCUSDT,1575158405045139,1575158405045139,true,ask,7571.55,0.047579
binance,BTCUSDT,1575158405045139,1575158405045139,true,ask,7572.01,0.0028
binance,BTCUSDT,1575158405045139,1575158405045139,true,ask,7572.03,0.116171
binance,BTCUSDT,1575158405045139,1575158405045139,true,ask,7572.04,0.2
binance,BTCUSDT,1575158405045139,1575158405045139,true,ask,7572.08,0.002
binance,BTCUSDT,1575158405045139,1575158405045139,true,ask,7572.09,0.15
binance,BTCUSDT,1575158405045139,1575158405045139,true,ask,7572.2,0.25
binance,BTCUSDT,1575158405045139,1575158405045139,true,ask,7572.42,0.133508
binance,BTCUSDT,1575158405045139,1575158405045139,true,ask,7572.44,0.002642
binance,BTCUSDT,1575158405045139,1575158405045139,true,ask,7572.46,0.001409
binance,BTCUSDT,1575158405045139,1575158405045139,true,ask,7572.5,0.25
binance,BTCUSDT,1575158405045139,1575158405045139,true,ask,7572.71,0.002649
binance,BTCUSDT,1575158405045139,1575158405045139,true,ask,7572.9,0.002978
binance,BTCUSDT,1575158405045139,1575158405045139,true,ask,7572.93,0.02
binance,BTCUSDT,1575158405045139,1575158405045139,true,ask,7573,0.04
binance,BTCUSDT,1575158405045139,1575158405045139,true,ask,7573.32,0.001991
binance,BTCUSDT,1575158405045139,1575158405045139,true,ask,7573.57,0.002341
binance,BTCUSDT,1575158405045139,1575158405045139,true,ask,7573.85,0.002131
binance,BTCUSDT,1575158405045139,1575158405045139,true,ask,7573.99,0.001519
binance,BTCUSDT,1575158405045139,1575158405045139,true,ask,7574.02,0.00199
binance,BTCUSDT,1575158405045139,1575158405045139,true,ask,7574.23,0.00199
binance,BTCUSDT,1575158405045139,1575158405045139,true,ask,7574.45,0.00199
binance,BTCUSDT,1575158405045139,1575158405045139,true,ask,7574.71,0.002373
binance,BTCUSDT,1575158405045139,1575158405045139,true,ask,7574.74,0.1
binance,BTCUSDT,1575158405045139,1575158405045139,true,ask,7574.75,0.023874
binance,BTCUSDT,1575158405045139,1575158405045139,true,ask,7574.87,0.00199
binance,BTCUSDT,1575158405045139,1575158405045139,true,ask,7574.88,0.0014
binance,BTCUSDT,1575158405045139,1575158405045139,true,ask,7574.99,0.004218
binance,BTCUSDT,1575158405045139,1575158405045139,true,ask,7575,3.793006
binance,BTCUSDT,1575158405045139,1575158405045139,true,ask,7575.5,0.0023
binance,BTCUSDT,1575158405045139,1575158405045139,true,ask,7575.68,0.030302
binance,BTCUSDT,1575158405045139,1575158405045139,true,ask,7575.75,0.030809
binance,BTCUSDT,1575158405045139,1575158405045139,true,ask,7575.82,0.01
binance,BTCUSDT,1575158405045139,1575158405045139,true,ask,7575.87,0.00398
binance,BTCUSDT,1575158405045139,1575158405045139,true,ask,7575.88,0.00199
binance,BTCUSDT,1575158405045139,1575158405045139,true,ask,7576,0.131995
binance,BTCUSDT,1575158405045139,1575158405045139,true,ask,7576.26,0.012008
binance,BTCUSDT,1575158405045139,1575158405045139,true,ask,7576.27,0.00143
binance,BTCUSDT,1575158405045139,1575158405045139,true,ask,7576.42,0.049534
binance,BTCUSDT,1575158405045139,1575158405045139,true,ask,7576.45,0.00199
binance,BTCUSDT,1575158405045139,1575158405045139,true,ask,7576.46,0.150801
binance,BTCUSDT,1575158405045139,1575158405045139,true,ask,7576.64,0.276401
binance,BTCUSDT,1575158405045139,1575158405045139,true,ask,7576.92,0.096728
binance,BTCUSDT,1575158405045139,1575158405045139,true,ask,7577.05,0.00398
binance,BTCUSDT,1575158405045139,1575158405045139,true,ask,7577.06,0.00199
binance,BTCUSDT,1575158405045139,1575158405045139,true,ask,7577.4,0.25
binance,BTCUSDT,1575158405045139,1575158405045139,true,ask,7577.44,0.1
binance,BTCUSDT,1575158405045139,1575158405045139,true,ask,7577.72,0.006868
binance,BTCUSDT,1575158405045139,1575158405045139,true,ask,7578,1.133676
binance,BTCUSDT,1575158405045139,1575158405045139,true,ask,7578.24,0.31516
binance,BTCUSDT,1575158405045139,1575158405045139,true,ask,7578.32,0.001989
binance,BTCUSDT,1575158405045139,1575158405045139,true,ask,7578.37,0.195086
binance,BTCUSDT,1575158405045139,1575158405045139,true,ask,7578.38,0.019268
binance,BTCUSDT,1575158405045139,1575158405045139,true,ask,7578.52,0.006394
binance,BTCUSDT,1575158405045139,1575158405045139,true,ask,7578.55,0.001989
binance,BTCUSDT,1575158405045139,1575158405045139,true,ask,7578.67,0.001989
binance,BTCUSDT,1575158405045139,1575158405045139,true,ask,7578.88,0.05
binance,BTCUSDT,1575158405045139,1575158405045139,true,ask,7578.89,0.001989
binance,BTCUSDT,1575158405045139,1575158405045139,true,ask,7578.99,1.307529
binance,BTCUSDT,1575158405045139,1575158405045139,true,ask,7579,45.039583
binance,BTCUSDT,1575158405045139,1575158405045139,true,ask,7579.01,0.042
binance,BTCUSDT,1575158405045139,1575158405045139,true,ask,7579.02,0.0538
binance,BTCUSDT,1575158405045139,1575158405045139,true,ask,7579.09,0.013987
binance,BTCUSDT,1575158405045139,1575158405045139,true,ask,7579.18,0.004539
binance,BTCUSDT,1575158405045139,1575158405045139,true,ask,7579.2,0.015
binance,BTCUSDT,1575158405045139,1575158405045139,true,ask,7579.34,0.022033
binance,BTCUSDT,1575158405045139,1575158405045139,true,ask,7579.61,0.001989
binance,BTCUSDT,1575158405045139,1575158405045139,true,ask,7579.71,0.002005
binance,BTCUSDT,1575158405045139,1575158405045139,true,ask,7579.9,0.117264
binance,BTCUSDT,1575158405045139,1575158405045139,true,ask,7579.94,0.00143
binance,BTCUSDT,1575158405045139,1575158405045139,true,ask,7579.99,0.011171
binance,BTCUSDT,1575158405045139,1575158405045139,true,ask,7580,7.793902
binance,BTCUSDT,1575158405045139,1575158405045139,true,ask,7580.07,0.001989
binance,BTCUSDT,1575158405045139,1575158405045139,true,ask,7580.15,0.00154
binance,BTCUSDT,1575158405045139,1575158405045139,true,ask,7580.18,0.001989
binance,BTCUSDT,1575158405045139,1575158405045139,true,ask,7580.23,0.00143
binance,BTCUSDT,1575158405045139,1575158405045139,true,ask,7580.43,0.001989
binance,BTCUSDT,1575158405045139,1575158405045139,true,ask,7580.55,0.052952
binance,BTCUSDT,1575158405045139,1575158405045139,true,ask,7580.64,0.001443
binance,BTCUSDT,1575158405045139,1575158405045139,true,ask,7580.76,0.001989
binance,BTCUSDT,1575158405045139,1575158405045139,true,ask,7580.82,0.001989
binance,BTCUSDT,1575158405045139,1575158405045139,true,ask,7580.86,0.001989
binance,BTCUSDT,1575158405045139,1575158405045139,true,ask,7581,0.092855
binance,BTCUSDT,1575158405045139,1575158405045139,true,ask,7581.18,0.001988
binance,BTCUSDT,1575158405045139,1575158405045139,true,ask,7581.2,0.001988
binance,BTCUSDT,1575158405045139,1575158405045139,true,ask,7581.36,0.002301
binance,BTCUSDT,1575158405045139,1575158405045139,true,ask,7581.44,1.0137
binance,BTCUSDT,1575158405045139,1575158405045139,true,ask,7581.54,0.01
binance,BTCUSDT,1575158405045139,1575158405045139,true,ask,7581.56,0.001988
binance,BTCUSDT,1575158405045139,1575158405045139,true,ask,7581.59,0.001988
binance,BTCUSDT,1575158405045139,1575158405045139,true,ask,7581.62,0.001988
binance,BTCUSDT,1575158405045139,1575158405045139,true,ask,7581.63,0.042827
binance,BTCUSDT,1575158405045139,1575158405045139,true,ask,7581.64,0.001988
binance,BTCUSDT,1575158405045139,1575158405045139,true,ask,7581.74,0.001988
binance,BTCUSDT,1575158405045139,1575158405045139,true,ask,7581.81,0.009273
binance,BTCUSDT,1575158405045139,1575158405045139,true,ask,7581.86,0.001988
binance,BTCUSDT,1575158405045139,1575158405045139,true,ask,7581.96,0.00504
binance,BTCUSDT,1575158405045139,1575158405045139,true,ask,7581.98,0.001988
binance,BTCUSDT,1575158405045139,1575158405045139,true,ask,7581.99,0.001988
binance,BTCUSDT,1575158405045139,1575158405045139,true,ask,7582,0.1
binance,BTCUSDT,1575158405045139,1575158405045139,true,ask,7582.06,0.004841
binance,BTCUSDT,1575158405045139,1575158405045139,true,ask,7582.07,0.001988
binance,BTCUSDT,1575158405045139,1575158405045139,true,ask,7582.11,0.00371
binance,BTCUSDT,1575158405045139,1575158405045139,true,ask,7582.12,0.1736
binance,BTCUSDT,1575158405045139,1575158405045139,true,ask,7582.15,0.003976
binance,BTCUSDT,1575158405045139,1575158405045139,true,ask,7582.27,0.00224
binance,BTCUSDT,1575158405045139,1575158405045139,true,ask,7582.28,0.017123
binance,BTCUSDT,1575158405045139,1575158405045139,true,ask,7582.33,0.001988
binance,BTCUSDT,1575158405045139,1575158405045139,true,ask,7582.41,0.003976
binance,BTCUSDT,1575158405045139,1575158405045139,true,ask,7582.48,0.001988
binance,BTCUSDT,1575158405045139,1575158405045139,true,ask,7582.5,1.7
binance,BTCUSDT,1575158405045139,1575158405045139,true,ask,7582.62,0.003976
binance,BTCUSDT,1575158405045139,1575158405045139,true,ask,7582.63,0.11
binance,BTCUSDT,1575158405045139,1575158405045139,true,ask,7582.92,0.022
binance,BTCUSDT,1575158405045139,1575158405045139,true,ask,7582.97,0.003
binance,BTCUSDT,1575158405045139,1575158405045139,true,ask,7583,0.062104
binance,BTCUSDT,1575158405045139,1575158405045139,true,ask,7583.14,0.012034
binance,BTCUSDT,1575158405045139,1575158405045139,true,ask,7583.16,0.003563
binance,BTCUSDT,1575158405045139,1575158405045139,true,ask,7583.21,0.001988
binance,BTCUSDT,1575158405045139,1575158405045139,true,ask,7583.36,0.003713
binance,BTCUSDT,1575158405045139,1575158405045139,true,ask,7583.45,0.001988
binance,BTCUSDT,1575158405045139,1575158405045139,true,ask,7583.49,0.00208
binance,BTCUSDT,1575158405045139,1575158405045139,true,ask,7583.51,0.001988
binance,BTCUSDT,1575158405045139,1575158405045139,true,ask,7583.53,0.001988
binance,BTCUSDT,1575158405045139,1575158405045139,true,ask,7583.57,0.146423
binance,BTCUSDT,1575158405045139,1575158405045139,true,ask,7583.73,0.001988
binance,BTCUSDT,1575158405045139,1575158405045139,true,ask,7583.98,2.904578
binance,BTCUSDT,1575158405045139,1575158405045139,true,ask,7584,0.772336
binance,BTCUSDT,1575158405045139,1575158405045139,true,ask,7584.06,0.016418
binance,BTCUSDT,1575158405045139,1575158405045139,true,ask,7584.09,0.024325
binance,BTCUSDT,1575158405045139,1575158405045139,true,ask,7584.17,0.031223
binance,BTCUSDT,1575158405045139,1575158405045139,true,ask,7584.21,0.00156
binance,BTCUSDT,1575158405045139,1575158405045139,true,ask,7584.35,0.001987
binance,BTCUSDT,1575158405045139,1575158405045139,true,ask,7584.41,0.001988
binance,BTCUSDT,1575158405045139,1575158405045139,true,ask,7584.58,0.17343
binance,BTCUSDT,1575158405045139,1575158405045139,true,ask,7584.67,0.160108
binance,BTCUSDT,1575158405045139,1575158405045139,true,ask,7584.77,0.001988
binance,BTCUSDT,1575158405045139,1575158405045139,true,ask,7584.82,0.001988
binance,BTCUSDT,1575158405045139,1575158405045139,true,ask,7585,2.596571
binance,BTCUSDT,1575158405045139,1575158405045139,true,ask,7585.07,0.001987
binance,BTCUSDT,1575158405045139,1575158405045139,true,ask,7585.14,0.007687
binance,BTCUSDT,1575158405045139,1575158405045139,true,ask,7585.34,0.013519
binance,BTCUSDT,1575158405045139,1575158405045139,true,ask,7585.42,0.001987
binance,BTCUSDT,1575158405045139,1575158405045139,true,ask,7585.43,0.001987
binance,BTCUSDT,1575158405045139,1575158405045139,true,ask,7585.61,0.001766
binance,BTCUSDT,1575158405045139,1575158405045139,true,ask,7585.71,0.00143
binance,BTCUSDT,1575158405045139,1575158405045139,true,ask,7585.9,0.001987
binance,BTCUSDT,1575158405045139,1575158405045139,true,ask,7585.92,0.003974
binance,BTCUSDT,1575158405045139,1575158405045139,true,ask,7585.93,0.001987
binance,BTCUSDT,1575158405045139,1575158405045139,true,ask,7586,0.151821
binance,BTCUSDT,1575158405045139,1575158405045139,true,ask,7586.11,0.012142
binance,BTCUSDT,1575158405045139,1575158405045139,true,ask,7586.14,0.001987
binance,BTCUSDT,1575158405045139,1575158405045139,true,ask,7586.34,0.001987
binance,BTCUSDT,1575158405045139,1575158405045139,true,ask,7586.37,0.001987
binance,BTCUSDT,1575158405045139,1575158405045139,true,ask,7586.47,2.35
binance,BTCUSDT,1575158405045139,1575158405045139,true,ask,7586.7,0.039037
binance,BTCUSDT,1575158405045139,1575158405045139,true,ask,7586.85,0.074199
binance,BTCUSDT,1575158405045139,1575158405045139,true,ask,7586.93,0.001987
binance,BTCUSDT,1575158405045139,1575158405045139,true,ask,7586.94,0.198926
binance,BTCUSDT,1575158405045139,1575158405045139,true,ask,7587,0.03
binance,BTCUSDT,1575158405045139,1575158405045139,true,ask,7587.01,0.008991
binance,BTCUSDT,1575158405045139,1575158405045139,true,ask,7587.37,0.001987
binance,BTCUSDT,1575158405045139,1575158405045139,true,ask,7587.41,0.001449
binance,BTCUSDT,1575158405045139,1575158405045139,true,ask,7587.47,0.001987
binance,BTCUSDT,1575158405045139,1575158405045139,true,ask,7587.51,0.0015
binance,BTCUSDT,1575158405045139,1575158405045139,true,ask,7587.7,0.009379
binance,BTCUSDT,1575158405045139,1575158405045139,true,ask,7588,25.313367
binance,BTCUSDT,1575158405045139,1575158405045139,true,ask,7588.07,0.003888
binance,BTCUSDT,1575158405045139,1575158405045139,true,ask,7588.17,0.129193
binance,BTCUSDT,1575158405045139,1575158405045139,true,ask,7588.32,0.01227
binance,BTCUSDT,1575158405045139,1575158405045139,true,ask,7588.55,0.001987
binance,BTCUSDT,1575158405045139,1575158405045139,true,ask,7588.57,0.0015
binance,BTCUSDT,1575158405045139,1575158405045139,true,ask,7588.59,0.001505
binance,BTCUSDT,1575158405045139,1575158405045139,true,ask,7588.62,0.00178
binance,BTCUSDT,1575158405045139,1575158405045139,true,ask,7588.66,0.001987
binance,BTCUSDT,1575158405045139,1575158405045139,true,ask,7588.69,0.007294
binance,BTCUSDT,1575158405045139,1575158405045139,true,ask,7588.88,0.1
binance,BTCUSDT,1575158405045139,1575158405045139,true,ask,7588.98,0.014109
binance,BTCUSDT,1575158405045139,1575158405045139,true,ask,7589,7.726354
binance,BTCUSDT,1575158405045139,1575158405045139,true,ask,7589.08,0.004238
binance,BTCUSDT,1575158405045139,1575158405045139,true,ask,7589.24,0.004143
binance,BTCUSDT,1575158405045139,1575158405045139,true,ask,7589.25,0.0075
binance,BTCUSDT,1575158405045139,1575158405045139,true,ask,7589.29,0.002964
binance,BTCUSDT,1575158405045139,1575158405045139,true,ask,7589.46,0.005747
binance,BTCUSDT,1575158405045139,1575158405045139,true,ask,7589.74,0.012019
binance,BTCUSDT,1575158405045139,1575158405045139,true,ask,7589.76,0.001582
binance,BTCUSDT,1575158405045139,1575158405045139,true,ask,7589.89,0.1
binance,BTCUSDT,1575158405045139,1575158405045139,true,ask,7589.98,0.002603
binance,BTCUSDT,1575158405045139,1575158405045139,true,ask,7590,10.638733
binance,BTCUSDT,1575158405045139,1575158405045139,true,ask,7590.1,0.156676
binance,BTCUSDT,1575158405045139,1575158405045139,true,ask,7590.15,0.114383
binance,BTCUSDT,1575158405045139,1575158405045139,true,ask,7590.4,0.253019
binance,BTCUSDT,1575158405045139,1575158405045139,true,ask,7590.85,0.001986
binance,BTCUSDT,1575158405045139,1575158405045139,true,ask,7590.94,0.001986
binance,BTCUSDT,1575158405045139,1575158405045139,true,ask,7591,0.001449
binance,BTCUSDT,1575158405045139,1575158405045139,true,ask,7591.11,0.005551
binance,BTCUSDT,1575158405045139,1575158405045139,true,ask,7591.45,0.001986
binance,BTCUSDT,1575158405045139,1575158405045139,true,ask,7591.83,0.002092
binance,BTCUSDT,1575158405045139,1575158405045139,true,ask,7591.89,0.001549
binance,BTCUSDT,1575158405045139,1575158405045139,true,ask,7591.92,0.00177
binance,BTCUSDT,1575158405045139,1575158405045139,true,ask,7592,0.00156
binance,BTCUSDT,1575158405045139,1575158405045139,true,ask,7592.13,0.003968
binance,BTCUSDT,1575158405045139,1575158405045139,true,ask,7592.26,0.0232
binance,BTCUSDT,1575158405045139,1575158405045139,true,ask,7592.98,0.021035
binance,BTCUSDT,1575158405045139,1575158405045139,true,ask,7593,0.307836
binance,BTCUSDT,1575158405045139,1575158405045139,true,ask,7593.01,0.826797
binance,BTCUSDT,1575158405045139,1575158405045139,true,ask,7593.22,0.003451
binance,BTCUSDT,1575158405045139,1575158405045139,true,ask,7593.51,0.001433
binance,BTCUSDT,1575158405045139,1575158405045139,true,ask,7594.03,0.030229
binance,BTCUSDT,1575158405045139,1575158405045139,true,ask,7594.04,0.003985
binance,BTCUSDT,1575158405045139,1575158405045139,true,ask,7594.06,0.001648
binance,BTCUSDT,1575158405045139,1575158405045139,true,ask,7594.46,0.011396
binance,BTCUSDT,1575158405045139,1575158405045139,true,ask,7594.48,0.001985
binance,BTCUSDT,1575158405045139,1575158405045139,true,ask,7594.56,0.001652
binance,BTCUSDT,1575158405045139,1575158405045139,true,ask,7594.59,0.001611
binance,BTCUSDT,1575158405045139,1575158405045139,true,ask,7594.93,0.00224
binance,BTCUSDT,1575158405045139,1575158405045139,true,ask,7595,2.646217
binance,BTCUSDT,1575158405045139,1575158405045139,true,ask,7595.31,0.007205
binance,BTCUSDT,1575158405045139,1575158405045139,true,ask,7595.49,0.005288
binance,BTCUSDT,1575158405045139,1575158405045139,true,ask,7595.5,0.010038
binance,BTCUSDT,1575158405045139,1575158405045139,true,ask,7595.54,0.058597
binance,BTCUSDT,1575158405045139,1575158405045139,true,ask,7595.61,0.01915
binance,BTCUSDT,1575158405045139,1575158405045139,true,ask,7595.93,0.654886
binance,BTCUSDT,1575158405045139,1575158405045139,true,ask,7596,0.02622
binance,BTCUSDT,1575158405045139,1575158405045139,true,ask,7596.05,0.0097
binance,BTCUSDT,1575158405045139,1575158405045139,true,ask,7596.25,0.01411
binance,BTCUSDT,1575158405045139,1575158405045139,true,ask,7596.41,0.005287
binance,BTCUSDT,1575158405045139,1575158405045139,true,ask,7596.54,0.066497
binance,BTCUSDT,1575158405045139,1575158405045139,true,ask,7596.65,0.005287
binance,BTCUSDT,1575158405045139,1575158405045139,true,ask,7596.87,0.001317
binance,BTCUSDT,1575158405045139,1575158405045139,true,ask,7596.93,0.042827
binance,BTCUSDT,1575158405045139,1575158405045139,true,ask,7597.01,0.008991
binance,BTCUSDT,1575158405045139,1575158405045139,true,ask,7597.1,0.663068
binance,BTCUSDT,1575158405045139,1575158405045139,true,ask,7597.17,0.001984
binance,BTCUSDT,1575158405045139,1575158405045139,true,ask,7597.3,0.002056
binance,BTCUSDT,1575158405045139,1575158405045139,true,ask,7597.48,0.005287
binance,BTCUSDT,1575158405045139,1575158405045139,true,ask,7597.8,0.590523
binance,BTCUSDT,1575158405045139,1575158405045139,true,ask,7597.85,0.067162
binance,BTCUSDT,1575158405045139,1575158405045139,true,ask,7597.87,0.00519
binance,BTCUSDT,1575158405045139,1575158405045139,true,ask,7598,1.761511
binance,BTCUSDT,1575158405045139,1575158405045139,true,ask,7598.01,0.002391
binance,BTCUSDT,1575158405045139,1575158405045139,true,ask,7598.82,0.019003
binance,BTCUSDT,1575158405045139,1575158405045139,true,ask,7598.87,0.005287
binance,BTCUSDT,1575158405045139,1575158405045139,true,ask,7598.88,0.433806
binance,BTCUSDT,1575158405045139,1575158405045139,true,ask,7598.95,0.06
binance,BTCUSDT,1575158405045139,1575158405045139,true,ask,7599,1.876053
binance,BTCUSDT,1575158405045139,1575158405045139,true,ask,7599.01,0.030011
binance,BTCUSDT,1575158405045139,1575158405045139,true,ask,7599.27,0.002372
binance,BTCUSDT,1575158405045139,1575158405045139,true,ask,7599.32,0.699999
binance,BTCUSDT,1575158405045139,1575158405045139,true,ask,7599.33,0.003576
binance,BTCUSDT,1575158405045139,1575158405045139,true,ask,7599.64,0.003048
binance,BTCUSDT,1575158405045139,1575158405045139,true,ask,7599.99,0.104928
binance,BTCUSDT,1575158405045139,1575158405045139,true,ask,7600,28.487932
binance,BTCUSDT,1575158405045139,1575158405045139,true,ask,7600.01,0.01047
binance,BTCUSDT,1575158405045139,1575158405045139,true,ask,7600.11,0.006604
binance,BTCUSDT,1575158405045139,1575158405045139,true,ask,7600.14,0.005804
binance,BTCUSDT,1575158405045139,1575158405045139,true,ask,7600.2,0.001452
binance,BTCUSDT,1575158405045139,1575158405045139,true,ask,7600.33,0.0023
binance,BTCUSDT,1575158405045139,1575158405045139,true,ask,7600.46,0.0015
binance,BTCUSDT,1575158405045139,1575158405045139,true,ask,7600.61,0.349174
binance,BTCUSDT,1575158405045139,1575158405045139,true,ask,7600.75,0.005285
binance,BTCUSDT,1575158405045139,1575158405045139,true,ask,7600.82,0.010337
binance,BTCUSDT,1575158405045139,1575158405045139,true,ask,7601,0.071137
binance,BTCUSDT,1575158405045139,1575158405045139,true,ask,7601.23,10.0358
binance,BTCUSDT,1575158405045139,1575158405045139,true,ask,7601.31,0.005284
binance,BTCUSDT,1575158405045139,1575158405045139,true,ask,7601.73,0.108503
binance,BTCUSDT,1575158405045139,1575158405045139,true,ask,7601.81,0.006603
binance,BTCUSDT,1575158405045139,1575158405045139,true,ask,7601.96,0.006602
binance,BTCUSDT,1575158405045139,1575158405045139,true,ask,7602,0.151712
binance,BTCUSDT,1575158405045139,1575158405045139,true,ask,7602.04,0.002615
binance,BTCUSDT,1575158405045139,1575158405045139,true,ask,7602.54,0.00133
binance,BTCUSDT,1575158405045139,1575158405045139,true,ask,7602.89,0.010617
binance,BTCUSDT,1575158405045139,1575158405045139,true,ask,7602.95,0.01227
binance,BTCUSDT,1575158405045139,1575158405045139,true,ask,7603.1,0.006602
binance,BTCUSDT,1575158405045139,1575158405045139,true,ask,7603.55,0.0558
binance,BTCUSDT,1575158405045139,1575158405045139,true,ask,7603.97,0.001488
binance,BTCUSDT,1575158405045139,1575158405045139,true,ask,7604.08,0.002331
binance,BTCUSDT,1575158405045139,1575158405045139,true,ask,7604.17,0.006601
binance,BTCUSDT,1575158405045139,1575158405045139,true,ask,7604.36,8.3475
binance,BTCUSDT,1575158405045139,1575158405045139,true,ask,7604.46,0.0066
binance,BTCUSDT,1575158405045139,1575158405045139,true,ask,7604.66,0.026725
binance,BTCUSDT,1575158405045139,1575158405045139,true,ask,7604.76,0.001643
binance,BTCUSDT,1575158405045139,1575158405045139,true,ask,7604.98,0.039628
binance,BTCUSDT,1575158405045139,1575158405045139,true,ask,7605,1.677452
binance,BTCUSDT,1575158405045139,1575158405045139,true,ask,7605.01,0.022032
binance,BTCUSDT,1575158405045139,1575158405045139,true,ask,7605.55,0.0035
binance,BTCUSDT,1575158405045139,1575158405045139,true,ask,7605.98,0.001894
binance,BTCUSDT,1575158405045139,1575158405045139,true,ask,7606.44,0.101585
binance,BTCUSDT,1575158405045139,1575158405045139,true,ask,7606.46,0.001387
binance,BTCUSDT,1575158405045139,1575158405045139,true,ask,7607,20.011
binance,BTCUSDT,1575158405045139,1575158405045139,true,ask,7607.01,0.008991
binance,BTCUSDT,1575158405045139,1575158405045139,true,ask,7607.25,0.002105
binance,BTCUSDT,1575158405045139,1575158405045139,true,ask,7607.44,0.00435
binance,BTCUSDT,1575158405045139,1575158405045139,true,ask,7607.59,0.042389
binance,BTCUSDT,1575158405045139,1575158405045139,true,ask,7607.89,0.014109
binance,BTCUSDT,1575158405045139,1575158405045139,true,ask,7608,0.199096
binance,BTCUSDT,1575158405045139,1575158405045139,true,ask,7608.13,0.002708
binance,BTCUSDT,1575158405045139,1575158405045139,true,ask,7608.69,0.001516
binance,BTCUSDT,1575158405045139,1575158405045139,true,ask,7608.86,0.00273
binance,BTCUSDT,1575158405045139,1575158405045139,true,ask,7608.88,0.3
binance,BTCUSDT,1575158405045139,1575158405045139,true,ask,7609.09,0.1
binance,BTCUSDT,1575158405045139,1575158405045139,true,ask,7609.35,0.001704
binance,BTCUSDT,1575158405045139,1575158405045139,true,ask,7609.41,0.01
binance,BTCUSDT,1575158405045139,1575158405045139,true,ask,7609.96,0.1
binance,BTCUSDT,1575158405045139,1575158405045139,true,ask,7610,11.871669
binance,BTCUSDT,1575158405045139,1575158405045139,true,ask,7610.69,0.003888
binance,BTCUSDT,1575158405045139,1575158405045139,true,ask,7610.71,0.001783
binance,BTCUSDT,1575158405045139,1575158405045139,true,ask,7610.87,0.006
binance,BTCUSDT,1575158405045139,1575158405045139,true,ask,7611,0.47606
binance,BTCUSDT,1575158405045139,1575158405045139,true,ask,7611.08,0.01
binance,BTCUSDT,1575158405045139,1575158405045139,true,ask,7611.19,0.048675
binance,BTCUSDT,1575158405045139,1575158405045139,true,ask,7611.37,0.381112
binance,BTCUSDT,1575158405045139,1575158405045139,true,ask,7611.47,0.001516
binance,BTCUSDT,1575158405045139,1575158405045139,true,ask,7611.63,0.001732
binance,BTCUSDT,1575158405045139,1575158405045139,true,ask,7611.66,0.001997
binance,BTCUSDT,1575158405045139,1575158405045139,true,ask,7612.24,0.044479
binance,BTCUSDT,1575158405045139,1575158405045139,true,ask,7612.42,0.0015
binance,BTCUSDT,1575158405045139,1575158405045139,true,ask,7612.8,0.00885
binance,BTCUSDT,1575158405045139,1575158405045139,true,ask,7612.88,0.101942
binance,BTCUSDT,1575158405045139,1575158405045139,true,ask,7612.99,0.001519
binance,BTCUSDT,1575158405045139,1575158405045139,true,ask,7613.01,0.01325
binance,BTCUSDT,1575158405045139,1575158405045139,true,ask,7613.02,0.006409
binance,BTCUSDT,1575158405045139,1575158405045139,true,ask,7613.25,1
binance,BTCUSDT,1575158405045139,1575158405045139,true,ask,7613.37,0.001828
binance,BTCUSDT,1575158405045139,1575158405045139,true,ask,7613.39,0.002649
binance,BTCUSDT,1575158405045139,1575158405045139,true,ask,7613.46,0.001721
binance,BTCUSDT,1575158405045139,1575158405045139,true,ask,7613.55,0.009914
binance,BTCUSDT,1575158405045139,1575158405045139,true,ask,7613.68,0.005007
binance,BTCUSDT,1575158405045139,1575158405045139,true,ask,7613.85,0.01
binance,BTCUSDT,1575158405045139,1575158405045139,true,ask,7614.16,0.005346
binance,BTCUSDT,1575158405045139,1575158405045139,true,ask,7614.23,0.217205
binance,BTCUSDT,1575158405045139,1575158405045139,true,ask,7614.28,0.00143
binance,BTCUSDT,1575158405045139,1575158405045139,true,ask,7614.63,0.029937
binance,BTCUSDT,1575158405045139,1575158405045139,true,ask,7614.94,0.00146
binance,BTCUSDT,1575158405045139,1575158405045139,true,ask,7615,11.18873
binance,BTCUSDT,1575158405045139,1575158405045139,true,ask,7615.07,0.112376
binance,BTCUSDT,1575158405045139,1575158405045139,true,ask,7615.23,0.134669
binance,BTCUSDT,1575158405045139,1575158405045139,true,ask,7615.38,0.009709
binance,BTCUSDT,1575158405045139,1575158405045139,true,ask,7615.42,0.01593
binance,BTCUSDT,1575158405045139,1575158405045139,true,ask,7615.57,0.112375
binance,BTCUSDT,1575158405045139,1575158405045139,true,ask,7615.7,0.063922
binance,BTCUSDT,1575158405045139,1575158405045139,true,ask,7615.85,0.001402
binance,BTCUSDT,1575158405045139,1575158405045139,true,ask,7616,0.0061
binance,BTCUSDT,1575158405045139,1575158405045139,true,ask,7616.08,0.009078
binance,BTCUSDT,1575158405045139,1575158405045139,true,ask,7616.19,0.003
binance,BTCUSDT,1575158405045139,1575158405045139,true,ask,7616.29,0.005994
binance,BTCUSDT,1575158405045139,1575158405045139,true,ask,7616.39,0.002751
binance,BTCUSDT,1575158405045139,1575158405045139,true,ask,7616.66,0.007053
binance,BTCUSDT,1575158405045139,1575158405045139,true,ask,7616.71,0.019268
binance,BTCUSDT,1575158405045139,1575158405045139,true,ask,7616.94,0.001902
binance,BTCUSDT,1575158405045139,1575158405045139,true,ask,7616.95,0.176964
binance,BTCUSDT,1575158405045139,1575158405045139,true,ask,7617,0.01
binance,BTCUSDT,1575158405045139,1575158405045139,true,ask,7617.05,0.003
binance,BTCUSDT,1575158405045139,1575158405045139,true,ask,7617.07,0.014488
binance,BTCUSDT,1575158405045139,1575158405045139,true,ask,7617.08,0.00255
binance,BTCUSDT,1575158405045139,1575158405045139,true,ask,7617.23,0.165451
binance,BTCUSDT,1575158405045139,1575158405045139,true,ask,7617.28,0.008991
binance,BTCUSDT,1575158405045139,1575158405045139,true,ask,7617.32,0.004344
binance,BTCUSDT,1575158405045139,1575158405045139,true,ask,7617.75,0.014479
binance,BTCUSDT,1575158405045139,1575158405045139,true,ask,7617.85,0.004444
binance,BTCUSDT,1575158405045139,1575158405045139,true,ask,7617.87,0.014479
binance,BTCUSDT,1575158405045139,1575158405045139,true,ask,7617.92,0.016921
binance,BTCUSDT,1575158405045139,1575158405045139,true,ask,7617.93,0.009
binance,BTCUSDT,1575158405045139,1575158405045139,true,ask,7618,1.740309
binance,BTCUSDT,1575158405045139,1575158405045139,true,ask,7618.01,0.013271
binance,BTCUSDT,1575158405045139,1575158405045139,true,ask,7618.23,0.17273
binance,BTCUSDT,1575158405045139,1575158405045139,true,ask,7618.24,0.010476
binance,BTCUSDT,1575158405045139,1575158405045139,true,ask,7618.42,0.014485
binance,BTCUSDT,1575158405045139,1575158405045139,true,ask,7618.5,0.014485
binance,BTCUSDT,1575158405045139,1575158405045139,true,ask,7618.7,0.001759
binance,BTCUSDT,1575158405045139,1575158405045139,true,ask,7618.76,0.014477
binance,BTCUSDT,1575158405045139,1575158405045139,true,ask,7618.83,0.011977
binance,BTCUSDT,1575158405045139,1575158405045139,true,ask,7618.84,0.00195
binance,BTCUSDT,1575158405045139,1575158405045139,true,ask,7618.89,0.004509
binance,BTCUSDT,1575158405045139,1575158405045139,true,ask,7618.99,0.657737
binance,BTCUSDT,1575158405045139,1575158405045139,true,ask,7619,0.170978
binance,BTCUSDT,1575158405045139,1575158405045139,true,ask,7619.23,0.072547
binance,BTCUSDT,1575158405045139,1575158405045139,true,ask,7619.28,0.014483
binance,BTCUSDT,1575158405045139,1575158405045139,true,ask,7619.35,0.001443
binance,BTCUSDT,1575158405045139,1575158405045139,true,ask,7619.76,0.014481
binance,BTCUSDT,1575158405045139,1575158405045139,true,ask,7619.79,0.001457
binance,BTCUSDT,1575158405045139,1575158405045139,true,ask,7619.82,0.029551
binance,BTCUSDT,1575158405045139,1575158405045139,true,ask,7619.93,0.014476
binance,BTCUSDT,1575158405045139,1575158405045139,true,ask,7620,60.781957
binance,BTCUSDT,1575158405045139,1575158405045139,true,ask,7620.25,0.00224
binance,BTCUSDT,1575158405045139,1575158405045139,true,ask,7620.47,0.012087
binance,BTCUSDT,1575158405045139,1575158405045139,true,ask,7620.48,0.014487
binance,BTCUSDT,1575158405045139,1575158405045139,true,ask,7620.6,0.03
binance,BTCUSDT,1575158405045139,1575158405045139,true,ask,7620.62,0.019713
binance,BTCUSDT,1575158405045139,1575158405045139,true,ask,7620.68,0.003972
binance,BTCUSDT,1575158405045139,1575158405045139,true,ask,7620.71,0.006816
binance,BTCUSDT,1575158405045139,1575158405045139,true,ask,7620.77,0.014473
binance,BTCUSDT,1575158405045139,1575158405045139,true,ask,7621,0.001837
binance,BTCUSDT,1575158405045139,1575158405045139,true,ask,7621.01,0.014485
binance,BTCUSDT,1575158405045139,1575158405045139,true,ask,7621.2,0.00473
binance,BTCUSDT,1575158405045139,1575158405045139,true,ask,7621.39,0.003561
binance,BTCUSDT,1575158405045139,1575158405045139,true,ask,7621.43,0.002985
binance,BTCUSDT,1575158405045139,1575158405045139,true,ask,7621.46,0.01447
binance,BTCUSDT,1575158405045139,1575158405045139,true,ask,7621.55,0.01447
binance,BTCUSDT,1575158405045139,1575158405045139,true,ask,7621.56,0.001622
binance,BTCUSDT,1575158405045139,1575158405045139,true,ask,7621.65,0.014483
binance,BTCUSDT,1575158405045139,1575158405045139,true,ask,7621.75,0.014484
binance,BTCUSDT,1575158405045139,1575158405045139,true,ask,7621.76,0.014483
binance,BTCUSDT,1575158405045139,1575158405045139,true,ask,7621.86,0.014483
binance,BTCUSDT,1575158405045139,1575158405045139,true,ask,7622,0.83263
binance,BTCUSDT,1575158405045139,1575158405045139,true,ask,7622.09,0.014483
binance,BTCUSDT,1575158405045139,1575158405045139,true,ask,7622.19,0.00153
binance,BTCUSDT,1575158405045139,1575158405045139,true,ask,7622.29,0.019709
binance,BTCUSDT,1575158405045139,1575158405045139,true,ask,7622.3,0.013519
binance,BTCUSDT,1575158405045139,1575158405045139,true,ask,7622.42,0.019709
binance,BTCUSDT,1575158405045139,1575158405045139,true,ask,7622.48,0.015358
binance,BTCUSDT,1575158405045139,1575158405045139,true,ask,7622.49,0.014476
binance,BTCUSDT,1575158405045139,1575158405045139,true,ask,7622.87,0.014481
binance,BTCUSDT,1575158405045139,1575158405045139,true,ask,7622.88,0.01
binance,BTCUSDT,1575158405045139,1575158405045139,true,ask,7622.96,0.014481
binance,BTCUSDT,1575158405045139,1575158405045139,true,ask,7622.97,0.002978
binance,BTCUSDT,1575158405045139,1575158405045139,true,ask,7623,0.01
binance,BTCUSDT,1575158405045139,1575158405045139,true,ask,7623.02,0.037254
binance,BTCUSDT,1575158405045139,1575158405045139,true,ask,7623.05,0.062104
binance,BTCUSDT,1575158405045139,1575158405045139,true,ask,7623.07,0.096728
binance,BTCUSDT,1575158405045139,1575158405045139,true,ask,7623.13,0.014481
binance,BTCUSDT,1575158405045139,1575158405045139,true,ask,7623.26,0.014481
binance,BTCUSDT,1575158405045139,1575158405045139,true,ask,7623.45,0.01448
binance,BTCUSDT,1575158405045139,1575158405045139,true,ask,7623.79,0.014473
binance,BTCUSDT,1575158405045139,1575158405045139,true,ask,7623.81,0.014473
binance,BTCUSDT,1575158405045139,1575158405045139,true,ask,7624,0.229412
binance,BTCUSDT,1575158405045139,1575158405045139,true,ask,7624.02,0.014479
binance,BTCUSDT,1575158405045139,1575158405045139,true,ask,7624.06,0.003
binance,BTCUSDT,1575158405045139,1575158405045139,true,ask,7624.09,0.014472
binance,BTCUSDT,1575158405045139,1575158405045139,true,ask,7624.15,4.363
binance,BTCUSDT,1575158405045139,1575158405045139,true,ask,7624.23,0.014479
binance,BTCUSDT,1575158405045139,1575158405045139,true,ask,7624.26,0.014479
binance,BTCUSDT,1575158405045139,1575158405045139,true,ask,7624.64,0.022032
binance,BTCUSDT,1575158405045139,1575158405045139,true,ask,7624.69,0.728948
binance,BTCUSDT,1575158405045139,1575158405045139,true,ask,7624.91,0.001968
binance,BTCUSDT,1575158405045139,1575158405045139,true,ask,7625,2.757525
binance,BTCUSDT,1575158405045139,1575158405045139,true,ask,7625.02,0.062681
binance,BTCUSDT,1575158405045139,1575158405045139,true,ask,7625.16,0.0023
binance,BTCUSDT,1575158405045139,1575158405045139,true,ask,7625.47,0.117264
binance,BTCUSDT,1575158405045139,1575158405045139,true,ask,7625.63,0.015956
binance,BTCUSDT,1575158405045139,1575158405045139,true,ask,7625.78,0.014476
binance,BTCUSDT,1575158405045139,1575158405045139,true,ask,7626.07,0.014474
binance,BTCUSDT,1575158405045139,1575158405045139,true,ask,7626.28,0.073815
binance,BTCUSDT,1575158405045139,1575158405045139,true,ask,7626.34,0.030482
binance,BTCUSDT,1575158405045139,1575158405045139,true,ask,7626.4,0.004762
binance,BTCUSDT,1575158405045139,1575158405045139,true,ask,7626.47,0.015894
binance,BTCUSDT,1575158405045139,1575158405045139,true,ask,7626.65,0.017365
binance,BTCUSDT,1575158405045139,1575158405045139,true,ask,7626.7,0.0028
binance,BTCUSDT,1575158405045139,1575158405045139,true,ask,7626.78,0.001502
binance,BTCUSDT,1575158405045139,1575158405045139,true,ask,7627,0.001442
binance,BTCUSDT,1575158405045139,1575158405045139,true,ask,7627.22,0.014474
binance,BTCUSDT,1575158405045139,1575158405045139,true,ask,7627.27,0.009273
binance,BTCUSDT,1575158405045139,1575158405045139,true,ask,7627.28,0.008991
binance,BTCUSDT,1575158405045139,1575158405045139,true,ask,7627.32,0.001617
binance,BTCUSDT,1575158405045139,1575158405045139,true,ask,7627.55,0.042827
binance,BTCUSDT,1575158405045139,1575158405045139,true,ask,7627.61,0.015907
binance,BTCUSDT,1575158405045139,1575158405045139,true,ask,7627.75,0.030371
binance,BTCUSDT,1575158405045139,1575158405045139,true,ask,7627.76,0.02
binance,BTCUSDT,1575158405045139,1575158405045139,true,ask,7628,0.043853
binance,BTCUSDT,1575158405045139,1575158405045139,true,ask,7628.32,0.01447
binance,BTCUSDT,1575158405045139,1575158405045139,true,ask,7628.35,0.003
binance,BTCUSDT,1575158405045139,1575158405045139,true,ask,7628.37,0.004131
binance,BTCUSDT,1575158405045139,1575158405045139,true,ask,7628.56,0.010642
binance,BTCUSDT,1575158405045139,1575158405045139,true,ask,7628.57,0.011124
binance,BTCUSDT,1575158405045139,1575158405045139,true,ask,7628.63,0.039037
binance,BTCUSDT,1575158405045139,1575158405045139,true,ask,7628.76,0.008001
binance,BTCUSDT,1575158405045139,1575158405045139,true,ask,7628.88,0.009367
binance,BTCUSDT,1575158405045139,1575158405045139,true,ask,7629,0.01
binance,BTCUSDT,1575158405045139,1575158405045139,true,ask,7629.05,0.01447
binance,BTCUSDT,1575158405045139,1575158405045139,true,ask,7629.24,0.014467
binance,BTCUSDT,1575158405045139,1575158405045139,true,ask,7629.29,0.014469
binance,BTCUSDT,1575158405045139,1575158405045139,true,ask,7629.96,0.014468
binance,BTCUSDT,1575158405045139,1575158405045139,true,ask,7630,20.651213
binance,BTCUSDT,1575158405045139,1575158405045139,true,ask,7630.18,0.014468
binance,BTCUSDT,1575158405045139,1575158405045139,true,ask,7630.24,0.014465
binance,BTCUSDT,1575158405045139,1575158405045139,true,ask,7630.25,0.01
binance,BTCUSDT,1575158405045139,1575158405045139,true,ask,7630.54,0.005804
binance,BTCUSDT,1575158405045139,1575158405045139,true,ask,7630.59,0.052604
binance,BTCUSDT,1575158405045139,1575158405045139,true,ask,7630.74,0.014466
binance,BTCUSDT,1575158405045139,1575158405045139,true,ask,7630.77,0.003
binance,BTCUSDT,1575158405045139,1575158405045139,true,ask,7630.83,0.005505
binance,BTCUSDT,1575158405045139,1575158405045139,true,ask,7631,1.17525
binance,BTCUSDT,1575158405045139,1575158405045139,true,ask,7631.21,0.006387
binance,BTCUSDT,1575158405045139,1575158405045139,true,ask,7631.57,0.00156
binance,BTCUSDT,1575158405045139,1575158405045139,true,ask,7632,2.130556
binance,BTCUSDT,1575158405045139,1575158405045139,true,ask,7632.44,0.006125
binance,BTCUSDT,1575158405045139,1575158405045139,true,ask,7632.74,0.003563
binance,BTCUSDT,1575158405045139,1575158405045139,true,ask,7632.84,0.01114
binance,BTCUSDT,1575158405045139,1575158405045139,true,ask,7632.89,0.303922
binance,BTCUSDT,1575158405045139,1575158405045139,true,ask,7632.91,0.004933
binance,BTCUSDT,1575158405045139,1575158405045139,true,ask,7633,1.054074
binance,BTCUSDT,1575158405045139,1575158405045139,true,ask,7633.3,0.003888
binance,BTCUSDT,1575158405045139,1575158405045139,true,ask,7633.33,0.0096
binance,BTCUSDT,1575158405045139,1575158405045139,true,ask,7633.4,2
binance,BTCUSDT,1575158405045139,1575158405045139,true,ask,7633.5,0.249985
binance,BTCUSDT,1575158405045139,1575158405045139,true,ask,7633.62,0.296671
binance,BTCUSDT,1575158405045139,1575158405045139,true,ask,7633.76,0.007294
binance,BTCUSDT,1575158405045139,1575158405045139,true,ask,7633.86,0.3
binance,BTCUSDT,1575158405045139,1575158405045139,true,ask,7634,1.687182
binance,BTCUSDT,1575158405045139,1575158405045139,true,ask,7634.5,0.014459
binance,BTCUSDT,1575158405045139,1575158405045139,true,ask,7634.69,0.004143
binance,BTCUSDT,1575158405045139,1575158405045139,true,ask,7634.75,0.005542
binance,BTCUSDT,1575158405045139,1575158405045139,true,ask,7634.81,0.0197
binance,BTCUSDT,1575158405045139,1575158405045139,true,ask,7634.96,0.001339
binance,BTCUSDT,1575158405045139,1575158405045139,true,ask,7635,0.79867
binance,BTCUSDT,1575158405045139,1575158405045139,true,ask,7635.01,0.007295
binance,BTCUSDT,1575158405045139,1575158405045139,true,ask,7635.13,0.001611
binance,BTCUSDT,1575158405045139,1575158405045139,true,ask,7635.26,0.0242
binance,BTCUSDT,1575158405045139,1575158405045139,true,ask,7635.34,2.5
binance,BTCUSDT,1575158405045139,1575158405045139,true,ask,7635.35,0.025963
binance,BTCUSDT,1575158405045139,1575158405045139,true,ask,7635.59,0.056344
binance,BTCUSDT,1575158405045139,1575158405045139,true,ask,7635.7,0.015887
binance,BTCUSDT,1575158405045139,1575158405045139,true,ask,7635.71,0.004444
binance,BTCUSDT,1575158405045139,1575158405045139,true,ask,7636,1
binance,BTCUSDT,1575158405045139,1575158405045139,true,ask,7636.17,0.12
binance,BTCUSDT,1575158405045139,1575158405045139,true,ask,7636.28,0.0015
binance,BTCUSDT,1575158405045139,1575158405045139,true,ask,7636.39,0.001886
binance,BTCUSDT,1575158405045139,1575158405045139,true,ask,7637,1.142715
binance,BTCUSDT,1575158405045139,1575158405045139,true,ask,7637.03,0.018347
binance,BTCUSDT,1575158405045139,1575158405045139,true,ask,7637.16,0.001522
binance,BTCUSDT,1575158405045139,1575158405045139,true,ask,7637.25,0.002523
binance,BTCUSDT,1575158405045139,1575158405045139,true,ask,7637.28,0.008991
binance,BTCUSDT,1575158405045139,1575158405045139,true,ask,7637.43,0.008021
binance,BTCUSDT,1575158405045139,1575158405045139,true,ask,7637.47,0.002673
binance,BTCUSDT,1575158405045139,1575158405045139,true,ask,7637.7,0.0015
binance,BTCUSDT,1575158405045139,1575158405045139,true,ask,7637.72,0.002056
binance,BTCUSDT,1575158405045139,1575158405045139,true,ask,7637.8,0.001338
binance,BTCUSDT,1575158405045139,1575158405045139,true,ask,7638,0.389539
binance,BTCUSDT,1575158405045139,1575158405045139,true,ask,7638.09,0.107281
binance,BTCUSDT,1575158405045139,1575158405045139,true,ask,7638.13,0.002391
binance,BTCUSDT,1575158405045139,1575158405045139,true,ask,7638.29,0.002483
binance,BTCUSDT,1575158405045139,1575158405045139,true,ask,7638.73,0.001869
binance,BTCUSDT,1575158405045139,1575158405045139,true,ask,7638.77,0.001398
binance,BTCUSDT,1575158405045139,1575158405045139,true,ask,7638.83,0.001338
binance,BTCUSDT,1575158405045139,1575158405045139,true,ask,7638.88,0.5
binance,BTCUSDT,1575158405045139,1575158405045139,true,ask,7639,0.836259
binance,BTCUSDT,1575158405045139,1575158405045139,true,ask,7639.3,0.014451
binance,BTCUSDT,1575158405045139,1575158405045139,true,ask,7639.6,0.004358
binance,BTCUSDT,1575158405045139,1575158405045139,true,ask,7640,3.501045
binance,BTCUSDT,1575158405045139,1575158405045139,true,ask,7640.2,0.006545
binance,BTCUSDT,1575158405045139,1575158405045139,true,ask,7640.32,0.021254
binance,BTCUSDT,1575158405045139,1575158405045139,true,ask,7640.43,0.00524
binance,BTCUSDT,1575158405045139,1575158405045139,true,ask,7640.61,0.001466
binance,BTCUSDT,1575158405045139,1575158405045139,true,ask,7640.81,0.001804
binance,BTCUSDT,1575158405045139,1575158405045139,true,ask,7640.83,0.014943
binance,BTCUSDT,1575158405045139,1575158405045139,true,ask,7641,0.314432
binance,BTCUSDT,1575158405045139,1575158405045139,true,ask,7641.02,0.009709
binance,BTCUSDT,1575158405045139,1575158405045139,true,ask,7641.58,0.052566
binance,BTCUSDT,1575158405045139,1575158405045139,true,ask,7641.65,0.068043
binance,BTCUSDT,1575158405045139,1575158405045139,true,ask,7642,1.409557
binance,BTCUSDT,1575158405045139,1575158405045139,true,ask,7642.1,0.001338
binance,BTCUSDT,1575158405045139,1575158405045139,true,ask,7642.23,0.001989
binance,BTCUSDT,1575158405045139,1575158405045139,true,ask,7642.39,0.011775
binance,BTCUSDT,1575158405045139,1575158405045139,true,ask,7642.85,0.044257
binance,BTCUSDT,1575158405045139,1575158405045139,true,ask,7643,5.011254
binance,BTCUSDT,1575158405045139,1575158405045139,true,ask,7643.03,0.014443
binance,BTCUSDT,1575158405045139,1575158405045139,true,ask,7643.11,0.002032
binance,BTCUSDT,1575158405045139,1575158405045139,true,ask,7643.59,0.001337
binance,BTCUSDT,1575158405045139,1575158405045139,true,ask,7643.61,0.019675
binance,BTCUSDT,1575158405045139,1575158405045139,true,ask,7644,1.06581
binance,BTCUSDT,1575158405045139,1575158405045139,true,ask,7644.44,0.0035
binance,BTCUSDT,1575158405045139,1575158405045139,true,ask,7644.57,0.003883
binance,BTCUSDT,1575158405045139,1575158405045139,true,ask,7644.65,0.158517
binance,BTCUSDT,1575158405045139,1575158405045139,true,ask,7644.73,0.001337
binance,BTCUSDT,1575158405045139,1575158405045139,true,ask,7644.75,0.007205
binance,BTCUSDT,1575158405045139,1575158405045139,true,ask,7644.92,0.001409
binance,BTCUSDT,1575158405045139,1575158405045139,true,ask,7645,0.525958
binance,BTCUSDT,1575158405045139,1575158405045139,true,ask,7645.16,0.006301
binance,BTCUSDT,1575158405045139,1575158405045139,true,ask,7645.19,0.00198
binance,BTCUSDT,1575158405045139,1575158405045139,true,ask,7645.2,0.001545
binance,BTCUSDT,1575158405045139,1575158405045139,true,ask,7645.48,0.004545
binance,BTCUSDT,1575158405045139,1575158405045139,true,ask,7645.56,0.00224
binance,BTCUSDT,1575158405045139,1575158405045139,true,ask,7645.88,0.001443
binance,BTCUSDT,1575158405045139,1575158405045139,true,ask,7645.98,0.001654
binance,BTCUSDT,1575158405045139,1575158405045139,true,ask,7646.09,0.001979
binance,BTCUSDT,1575158405045139,1575158405045139,true,ask,7646.1,0.014437
binance,BTCUSDT,1575158405045139,1575158405045139,true,ask,7646.15,0.096728
binance,BTCUSDT,1575158405045139,1575158405045139,true,ask,7646.42,0.001337
binance,BTCUSDT,1575158405045139,1575158405045139,true,ask,7646.43,0.001979
binance,BTCUSDT,1575158405045139,1575158405045139,true,ask,7646.63,0.067162
binance,BTCUSDT,1575158405045139,1575158405045139,true,ask,7646.78,0.00177
binance,BTCUSDT,1575158405045139,1575158405045139,true,ask,7647,0.438441
binance,BTCUSDT,1575158405045139,1575158405045139,true,ask,7647.03,0.154471
binance,BTCUSDT,1575158405045139,1575158405045139,true,ask,7647.12,0.014433
binance,BTCUSDT,1575158405045139,1575158405045139,true,ask,7647.28,0.008991
binance,BTCUSDT,1575158405045139,1575158405045139,true,ask,7647.57,0.074729
binance,BTCUSDT,1575158405045139,1575158405045139,true,ask,7647.68,0.002929
binance,BTCUSDT,1575158405045139,1575158405045139,true,ask,7647.83,0.00567
binance,BTCUSDT,1575158405045139,1575158405045139,true,ask,7647.87,0.014434
binance,BTCUSDT,1575158405045139,1575158405045139,true,ask,7647.96,0.002708
binance,BTCUSDT,1575158405045139,1575158405045139,true,ask,7648,0.0014
binance,BTCUSDT,1575158405045139,1575158405045139,true,ask,7648.11,0.014434
binance,BTCUSDT,1575158405045139,1575158405045139,true,ask,7648.12,0.5
binance,BTCUSDT,1575158405045139,1575158405045139,true,ask,7648.22,0.380769
binance,BTCUSDT,1575158405045139,1575158405045139,true,ask,7648.37,0.001979
binance,BTCUSDT,1575158405045139,1575158405045139,true,ask,7648.45,0.003958
binance,BTCUSDT,1575158405045139,1575158405045139,true,ask,7648.56,0.002887
binance,BTCUSDT,1575158405045139,1575158405045139,true,ask,7648.61,0.001522
binance,BTCUSDT,1575158405045139,1575158405045139,true,ask,7648.71,0.00273
binance,BTCUSDT,1575158405045139,1575158405045139,true,ask,7648.72,0.005747
binance,BTCUSDT,1575158405045139,1575158405045139,true,ask,7648.82,0.001979
binance,BTCUSDT,1575158405045139,1575158405045139,true,ask,7648.84,0.215264
binance,BTCUSDT,1575158405045139,1575158405045139,true,ask,7648.95,0.003433
binance,BTCUSDT,1575158405045139,1575158405045139,true,ask,7649,0.849707
binance,BTCUSDT,1575158405045139,1575158405045139,true,ask,7649.02,0.113921
binance,BTCUSDT,1575158405045139,1575158405045139,true,ask,7649.1,0.002151
binance,BTCUSDT,1575158405045139,1575158405045139,true,ask,7649.14,0.001979
binance,BTCUSDT,1575158405045139,1575158405045139,true,ask,7649.27,0.029937
binance,BTCUSDT,1575158405045139,1575158405045139,true,ask,7649.31,0.068894
binance,BTCUSDT,1575158405045139,1575158405045139,true,ask,7649.5,0.001438
binance,BTCUSDT,1575158405045139,1575158405045139,true,ask,7649.61,0.004841
binance,BTCUSDT,1575158405045139,1575158405045139,true,ask,7649.62,0.014432
binance,BTCUSDT,1575158405045139,1575158405045139,true,ask,7649.69,0.001336
binance,BTCUSDT,1575158405045139,1575158405045139,true,ask,7649.7,0.5
binance,BTCUSDT,1575158405045139,1575158405045139,true,ask,7649.71,0.001336
binance,BTCUSDT,1575158405045139,1575158405045139,true,ask,7649.74,0.001336
binance,BTCUSDT,1575158405045139,1575158405045139,true,ask,7649.83,0.066538
binance,BTCUSDT,1575158405045139,1575158405045139,true,ask,7649.91,0.001978
binance,BTCUSDT,1575158405045139,1575158405045139,true,ask,7649.94,0.001336
binance,BTCUSDT,1575158405045139,1575158405045139,true,ask,7649.99,0.014341
binance,BTCUSDT,1575158405045139,1575158405045139,true,ask,7650,42.079653
binance,BTCUSDT,1575158405045139,1575158405045139,true,ask,7650.04,0.014429
binance,BTCUSDT,1575158405045139,1575158405045139,true,ask,7650.23,0.039628
binance,BTCUSDT,1575158405045139,1575158405045139,true,ask,7650.39,0.014429
binance,BTCUSDT,1575158405045139,1575158405045139,true,ask,7650.45,0.001336
binance,BTCUSDT,1575158405045139,1575158405045139,true,ask,7650.51,0.053528
binance,BTCUSDT,1575158405045139,1575158405045139,true,ask,7650.72,0.012876
binance,BTCUSDT,1575158405045139,1575158405045139,true,ask,7650.81,0.025
binance,BTCUSDT,1575158405045139,1575158405045139,true,ask,7650.84,0.002897
binance,BTCUSDT,1575158405045139,1575158405045139,true,ask,7650.85,0.001336
binance,BTCUSDT,1575158405045139,1575158405045139,true,ask,7650.89,0.001439
binance,BTCUSDT,1575158405045139,1575158405045139,true,ask,7650.99,0.014423
binance,BTCUSDT,1575158405045139,1575158405045139,true,ask,7651,0.106446
binance,BTCUSDT,1575158405045139,1575158405045139,true,ask,7651.05,0.014827
binance,BTCUSDT,1575158405045139,1575158405045139,true,ask,7651.15,0.014428
binance,BTCUSDT,1575158405045139,1575158405045139,true,ask,7651.17,0.001336
binance,BTCUSDT,1575158405045139,1575158405045139,true,ask,7651.38,0.001978
binance,BTCUSDT,1575158405045139,1575158405045139,true,ask,7651.58,0.011042
binance,BTCUSDT,1575158405045139,1575158405045139,true,ask,7651.79,0.001336
binance,BTCUSDT,1575158405045139,1575158405045139,true,ask,7651.89,0.040149
binance,BTCUSDT,1575158405045139,1575158405045139,true,ask,7651.91,0.002
binance,BTCUSDT,1575158405045139,1575158405045139,true,ask,7652,0.095352
binance,BTCUSDT,1575158405045139,1575158405045139,true,ask,7652.08,0.019343
binance,BTCUSDT,1575158405045139,1575158405045139,true,ask,7652.17,0.009141
binance,BTCUSDT,1575158405045139,1575158405045139,true,ask,7652.32,0.001336
binance,BTCUSDT,1575158405045139,1575158405045139,true,ask,7652.37,0.014421
binance,BTCUSDT,1575158405045139,1575158405045139,true,ask,7652.54,0.017548
binance,BTCUSDT,1575158405045139,1575158405045139,true,ask,7652.61,0.001336
binance,BTCUSDT,1575158405045139,1575158405045139,true,ask,7652.68,0.001336
binance,BTCUSDT,1575158405045139,1575158405045139,true,ask,7652.75,0.006801
binance,BTCUSDT,1575158405045139,1575158405045139,true,ask,7652.76,0.001334
binance,BTCUSDT,1575158405045139,1575158405045139,true,ask,7652.79,0.001334
binance,BTCUSDT,1575158405045139,1575158405045139,true,ask,7652.82,0.148439
binance,BTCUSDT,1575158405045139,1575158405045139,true,ask,7652.85,0.001336
binance,BTCUSDT,1575158405045139,1575158405045139,true,ask,7652.91,0.001334
binance,BTCUSDT,1575158405045139,1575158405045139,true,ask,7653,0.01
binance,BTCUSDT,1575158405045139,1575158405045139,true,ask,7653.05,0.06
binance,BTCUSDT,1575158405045139,1575158405045139,true,ask,7653.06,0.004707
binance,BTCUSDT,1575158405045139,1575158405045139,true,ask,7653.17,0.001336
binance,BTCUSDT,1575158405045139,1575158405045139,true,ask,7653.28,0.001336
binance,BTCUSDT,1575158405045139,1575158405045139,true,ask,7653.32,0.039756
binance,BTCUSDT,1575158405045139,1575158405045139,true,ask,7653.35,0.001433
binance,BTCUSDT,1575158405045139,1575158405045139,true,ask,7653.41,0.003156
binance,BTCUSDT,1575158405045139,1575158405045139,true,ask,7653.47,0.001977
binance,BTCUSDT,1575158405045139,1575158405045139,true,ask,7653.57,0.004444
binance,BTCUSDT,1575158405045139,1575158405045139,true,ask,7653.6,0.014418
binance,BTCUSDT,1575158405045139,1575158405045139,true,ask,7653.71,0.001336
binance,BTCUSDT,1575158405045139,1575158405045139,true,ask,7653.92,0.001977
binance,BTCUSDT,1575158405045139,1575158405045139,true,ask,7653.95,0.001336
binance,BTCUSDT,1575158405045139,1575158405045139,true,ask,7653.97,0.001336
binance,BTCUSDT,1575158405045139,1575158405045139,true,ask,7653.98,0.5
binance,BTCUSDT,1575158405045139,1575158405045139,true,ask,7654.03,0.001336
binance,BTCUSDT,1575158405045139,1575158405045139,true,ask,7654.04,0.008794
binance,BTCUSDT,1575158405045139,1575158405045139,true,ask,7654.07,0.003985
binance,BTCUSDT,1575158405045139,1575158405045139,true,ask,7654.09,0.001977
binance,BTCUSDT,1575158405045139,1575158405045139,true,ask,7654.13,0.001336
binance,BTCUSDT,1575158405045139,1575158405045139,true,ask,7654.26,0.001977
binance,BTCUSDT,1575158405045139,1575158405045139,true,ask,7654.32,0.454643
binance,BTCUSDT,1575158405045139,1575158405045139,true,ask,7654.54,0.1
binance,BTCUSDT,1575158405045139,1575158405045139,true,ask,7654.66,0.001704
binance,BTCUSDT,1575158405045139,1575158405045139,true,ask,7654.78,0.01287
binance,BTCUSDT,1575158405045139,1575158405045139,true,ask,7654.81,0.0038
binance,BTCUSDT,1575158405045139,1575158405045139,true,ask,7654.99,0.001519
binance,BTCUSDT,1575158405045139,1575158405045139,true,ask,7655,1.006564
binance,BTCUSDT,1575158405045139,1575158405045139,true,ask,7655.04,0.019268
binance,BTCUSDT,1575158405045139,1575158405045139,true,ask,7655.14,0.001977
binance,BTCUSDT,1575158405045139,1575158405045139,true,ask,7655.42,0.036936
binance,BTCUSDT,1575158405045139,1575158405045139,true,ask,7655.64,0.026435
binance,BTCUSDT,1575158405045139,1575158405045139,true,ask,7655.65,0.013847
binance,BTCUSDT,1575158405045139,1575158405045139,true,ask,7655.68,0.207708
binance,BTCUSDT,1575158405045139,1575158405045139,true,ask,7655.72,0.001334
binance,BTCUSDT,1575158405045139,1575158405045139,true,ask,7655.82,0.065133
binance,BTCUSDT,1575158405045139,1575158405045139,true,ask,7655.92,0.003888
binance,BTCUSDT,1575158405045139,1575158405045139,true,ask,7655.93,0.009914
binance,BTCUSDT,1575158405045139,1575158405045139,true,ask,7656,0.113314
binance,BTCUSDT,1575158405045139,1575158405045139,true,ask,7656.21,0.874848
binance,BTCUSDT,1575158405045139,1575158405045139,true,ask,7656.33,0.002616
binance,BTCUSDT,1575158405045139,1575158405045139,true,ask,7656.44,0.001392
binance,BTCUSDT,1575158405045139,1575158405045139,true,ask,7656.46,0.150801
binance,BTCUSDT,1575158405045139,1575158405045139,true,ask,7656.56,0.528728
binance,BTCUSDT,1575158405045139,1575158405045139,true,ask,7656.57,0.003
binance,BTCUSDT,1575158405045139,1575158405045139,true,ask,7656.67,0.001335
binance,BTCUSDT,1575158405045139,1575158405045139,true,ask,7656.81,0.037677
binance,BTCUSDT,1575158405045139,1575158405045139,true,ask,7657.03,0.001335
binance,BTCUSDT,1575158405045139,1575158405045139,true,ask,7657.05,7.042
binance,BTCUSDT,1575158405045139,1575158405045139,true,ask,7657.07,0.001335
binance,BTCUSDT,1575158405045139,1575158405045139,true,ask,7657.14,0.003817
binance,BTCUSDT,1575158405045139,1575158405045139,true,ask,7657.22,0.002594
binance,BTCUSDT,1575158405045139,1575158405045139,true,ask,7657.28,0.008991
binance,BTCUSDT,1575158405045139,1575158405045139,true,ask,7657.4,0.196719
binance,BTCUSDT,1575158405045139,1575158405045139,true,ask,7658,29.33669
binance,BTCUSDT,1575158405045139,1575158405045139,true,ask,7658.06,0.002989
binance,BTCUSDT,1575158405045139,1575158405045139,true,ask,7658.16,0.042827
binance,BTCUSDT,1575158405045139,1575158405045139,true,ask,7658.22,0.00224
binance,BTCUSDT,1575158405045139,1575158405045139,true,ask,7658.23,0.002822
binance,BTCUSDT,1575158405045139,1575158405045139,true,ask,7658.31,0.001335
binance,BTCUSDT,1575158405045139,1575158405045139,true,ask,7658.7,0.048675
binance,BTCUSDT,1575158405045139,1575158405045139,true,ask,7658.71,0.001335
binance,BTCUSDT,1575158405045139,1575158405045139,true,ask,7658.87,0.381112
binance,BTCUSDT,1575158405045139,1575158405045139,true,ask,7658.94,0.004
binance,BTCUSDT,1575158405045139,1575158405045139,true,ask,7659,0.012035
binance,BTCUSDT,1575158405045139,1575158405045139,true,ask,7659.1,0.00267
binance,BTCUSDT,1575158405045139,1575158405045139,true,ask,7659.13,0.003576
binance,BTCUSDT,1575158405045139,1575158405045139,true,ask,7659.26,0.013519
binance,BTCUSDT,1575158405045139,1575158405045139,true,ask,7659.9,0.01806
binance,BTCUSDT,1575158405045139,1575158405045139,true,ask,7660,0.661937
binance,BTCUSDT,1575158405045139,1575158405045139,true,ask,7660.08,0.001522
binance,BTCUSDT,1575158405045139,1575158405045139,true,ask,7660.14,0.0041
binance,BTCUSDT,1575158405045139,1575158405045139,true,ask,7660.48,0.001531
binance,BTCUSDT,1575158405045139,1575158405045139,true,ask,7660.99,0.008068
binance,BTCUSDT,1575158405045139,1575158405045139,true,ask,7661,0.05
binance,BTCUSDT,1575158405045139,1575158405045139,true,ask,7661.05,0.001333
binance,BTCUSDT,1575158405045139,1575158405045139,true,ask,7661.1,0.001334
binance,BTCUSDT,1575158405045139,1575158405045139,true,ask,7661.22,0.001334
binance,BTCUSDT,1575158405045139,1575158405045139,true,ask,7661.74,0.025659
binance,BTCUSDT,1575158405045139,1575158405045139,true,ask,7661.75,0.001394
binance,BTCUSDT,1575158405045139,1575158405045139,true,ask,7661.86,0.001334
binance,BTCUSDT,1575158405045139,1575158405045139,true,ask,7661.92,0.001334
binance,BTCUSDT,1575158405045139,1575158405045139,true,ask,7661.93,0.001334
binance,BTCUSDT,1575158405045139,1575158405045139,true,ask,7662.02,0.001334
binance,BTCUSDT,1575158405045139,1575158405045139,true,ask,7662.45,0.001334
binance,BTCUSDT,1575158405045139,1575158405045139,true,ask,7662.61,0.003152
binance,BTCUSDT,1575158405045139,1575158405045139,true,ask,7662.98,0.001334
binance,BTCUSDT,1575158405045139,1575158405045139,true,ask,7663.1,0.062104
binance,BTCUSDT,1575158405045139,1575158405045139,true,ask,7663.26,0.01
binance,BTCUSDT,1575158405045139,1575158405045139,true,ask,7663.29,0.001435
binance,BTCUSDT,1575158405045139,1575158405045139,true,ask,7663.33,0.007053
binance,BTCUSDT,1575158405045139,1575158405045139,true,ask,7663.34,0.001334
binance,BTCUSDT,1575158405045139,1575158405045139,true,ask,7663.38,0.011396
binance,BTCUSDT,1575158405045139,1575158405045139,true,ask,7663.41,0.001334
binance,BTCUSDT,1575158405045139,1575158405045139,true,ask,7663.76,0.001333
binance,BTCUSDT,1575158405045139,1575158405045139,true,ask,7664,3.5
binance,BTCUSDT,1575158405045139,1575158405045139,true,bid,7539.41,0.226735
binance,BTCUSDT,1575158405045139,1575158405045139,true,bid,7539.21,1.804031
binance,BTCUSDT,1575158405045139,1575158405045139,true,bid,7539.18,0.332322
binance,BTCUSDT,1575158405045139,1575158405045139,true,bid,7539,0.013245
binance,BTCUSDT,1575158405045139,1575158405045139,true,bid,7538.48,0.03
binance,BTCUSDT,1575158405045139,1575158405045139,true,bid,7538.47,0.275651
binance,BTCUSDT,1575158405045139,1575158405045139,true,bid,7538.44,0.024833
binance,BTCUSDT,1575158405045139,1575158405045139,true,bid,7538.23,0.3
binance,BTCUSDT,1575158405045139,1575158405045139,true,bid,7538.21,0.185752
binance,BTCUSDT,1575158405045139,1575158405045139,true,bid,7538.18,0.318149
binance,BTCUSDT,1575158405045139,1575158405045139,true,bid,7538.13,0.019529
binance,BTCUSDT,1575158405045139,1575158405045139,true,bid,7538.03,0.01144
binance,BTCUSDT,1575158405045139,1575158405045139,true,bid,7537.42,0.2
binance,BTCUSDT,1575158405045139,1575158405045139,true,bid,7537.41,0.093354
binance,BTCUSDT,1575158405045139,1575158405045139,true,bid,7537.35,0.092376
binance,BTCUSDT,1575158405045139,1575158405045139,true,bid,7537.34,1
binance,BTCUSDT,1575158405045139,1575158405045139,true,bid,7537.27,0.020084
binance,BTCUSDT,1575158405045139,1575158405045139,true,bid,7537.05,3.470245
binance,BTCUSDT,1575158405045139,1575158405045139,true,bid,7537.02,0.07868
binance,BTCUSDT,1575158405045139,1575158405045139,true,bid,7536.5,0.4
binance,BTCUSDT,1575158405045139,1575158405045139,true,bid,7536.21,0.096465
binance,BTCUSDT,1575158405045139,1575158405045139,true,bid,7536.09,0.033174
binance,BTCUSDT,1575158405045139,1575158405045139,true,bid,7536.06,0.021189
binance,BTCUSDT,1575158405045139,1575158405045139,true,bid,7536,0.025
binance,BTCUSDT,1575158405045139,1575158405045139,true,bid,7535.18,0.24
binance,BTCUSDT,1575158405045139,1575158405045139,true,bid,7535.16,0.075589
binance,BTCUSDT,1575158405045139,1575158405045139,true,bid,7535.13,1.44095
binance,BTCUSDT,1575158405045139,1575158405045139,true,bid,7535.12,0.049161
binance,BTCUSDT,1575158405045139,1575158405045139,true,bid,7535.01,0.026543
binance,BTCUSDT,1575158405045139,1575158405045139,true,bid,7535,4.226066
binance,BTCUSDT,1575158405045139,1575158405045139,true,bid,7534.98,6
binance,BTCUSDT,1575158405045139,1575158405045139,true,bid,7534.93,0.299641
binance,BTCUSDT,1575158405045139,1575158405045139,true,bid,7534.75,0.5
binance,BTCUSDT,1575158405045139,1575158405045139,true,bid,7534.52,0.0097
binance,BTCUSDT,1575158405045139,1575158405045139,true,bid,7534.02,0.020901
binance,BTCUSDT,1575158405045139,1575158405045139,true,bid,7534,0.00146
binance,BTCUSDT,1575158405045139,1575158405045139,true,bid,7533.96,21.189864
binance,BTCUSDT,1575158405045139,1575158405045139,true,bid,7533.9,0.019424
binance,BTCUSDT,1575158405045139,1575158405045139,true,bid,7533.83,0.160282
binance,BTCUSDT,1575158405045139,1575158405045139,true,bid,7533.5,0.215465
binance,BTCUSDT,1575158405045139,1575158405045139,true,bid,7533.3,0.5
binance,BTCUSDT,1575158405045139,1575158405045139,true,bid,7533.17,0.398236
binance,BTCUSDT,1575158405045139,1575158405045139,true,bid,7533.15,0.005
binance,BTCUSDT,1575158405045139,1575158405045139,true,bid,7533,0.00146
binance,BTCUSDT,1575158405045139,1575158405045139,true,bid,7532.92,0.038848
binance,BTCUSDT,1575158405045139,1575158405045139,true,bid,7532.89,0.001328
binance,BTCUSDT,1575158405045139,1575158405045139,true,bid,7532.82,0.001328
binance,BTCUSDT,1575158405045139,1575158405045139,true,bid,7532.6,0.8
binance,BTCUSDT,1575158405045139,1575158405045139,true,bid,7532.59,0.006785
binance,BTCUSDT,1575158405045139,1575158405045139,true,bid,7532.09,0.2
binance,BTCUSDT,1575158405045139,1575158405045139,true,bid,7532,0.00146
binance,BTCUSDT,1575158405045139,1575158405045139,true,bid,7531.7,0.5
binance,BTCUSDT,1575158405045139,1575158405045139,true,bid,7531.66,0.398291
binance,BTCUSDT,1575158405045139,1575158405045139,true,bid,7531.64,0.00224
binance,BTCUSDT,1575158405045139,1575158405045139,true,bid,7531.33,0.2
binance,BTCUSDT,1575158405045139,1575158405045139,true,bid,7531.27,0.010608
binance,BTCUSDT,1575158405045139,1575158405045139,true,bid,7531.17,0.024697
binance,BTCUSDT,1575158405045139,1575158405045139,true,bid,7531.15,0.01002
binance,BTCUSDT,1575158405045139,1575158405045139,true,bid,7531.08,0.053035
binance,BTCUSDT,1575158405045139,1575158405045139,true,bid,7531.04,0.001459
binance,BTCUSDT,1575158405045139,1575158405045139,true,bid,7531,0.00146
binance,BTCUSDT,1575158405045139,1575158405045139,true,bid,7530.88,0.4189
binance,BTCUSDT,1575158405045139,1575158405045139,true,bid,7530.76,0.644363
binance,BTCUSDT,1575158405045139,1575158405045139,true,bid,7530.14,0.398393
binance,BTCUSDT,1575158405045139,1575158405045139,true,bid,7530.01,0.033233
binance,BTCUSDT,1575158405045139,1575158405045139,true,bid,7530,22.427703
binance,BTCUSDT,1575158405045139,1575158405045139,true,bid,7529.98,1.491623
binance,BTCUSDT,1575158405045139,1575158405045139,true,bid,7529.54,1.853
binance,BTCUSDT,1575158405045139,1575158405045139,true,bid,7529.51,0.009601
binance,BTCUSDT,1575158405045139,1575158405045139,true,bid,7529.07,0.1
binance,BTCUSDT,1575158405045139,1575158405045139,true,bid,7529.01,16.457032
binance,BTCUSDT,1575158405045139,1575158405045139,true,bid,7529,0.0177
binance,BTCUSDT,1575158405045139,1575158405045139,true,bid,7528.91,0.001329
binance,BTCUSDT,1575158405045139,1575158405045139,true,bid,7528.75,0.001329
binance,BTCUSDT,1575158405045139,1575158405045139,true,bid,7528.62,0.398203
binance,BTCUSDT,1575158405045139,1575158405045139,true,bid,7528.57,0.00143
binance,BTCUSDT,1575158405045139,1575158405045139,true,bid,7528.31,0.001592
binance,BTCUSDT,1575158405045139,1575158405045139,true,bid,7528.21,0.0192
binance,BTCUSDT,1575158405045139,1575158405045139,true,bid,7528.19,12
binance,BTCUSDT,1575158405045139,1575158405045139,true,bid,7528,0.001461
binance,BTCUSDT,1575158405045139,1575158405045139,true,bid,7527.22,0.00241
binance,BTCUSDT,1575158405045139,1575158405045139,true,bid,7527.19,0.00855
binance,BTCUSDT,1575158405045139,1575158405045139,true,bid,7527.11,0.398203
binance,BTCUSDT,1575158405045139,1575158405045139,true,bid,7527,0.001461
binance,BTCUSDT,1575158405045139,1575158405045139,true,bid,7526.94,0.8329
binance,BTCUSDT,1575158405045139,1575158405045139,true,bid,7526.79,0.058253
binance,BTCUSDT,1575158405045139,1575158405045139,true,bid,7526.32,0.116506
binance,BTCUSDT,1575158405045139,1575158405045139,true,bid,7526,0.001461
binance,BTCUSDT,1575158405045139,1575158405045139,true,bid,7525.83,0.0023
binance,BTCUSDT,1575158405045139,1575158405045139,true,bid,7525.59,0.398203
binance,BTCUSDT,1575158405045139,1575158405045139,true,bid,7525.33,0.00234
binance,BTCUSDT,1575158405045139,1575158405045139,true,bid,7525.11,0.001329
binance,BTCUSDT,1575158405045139,1575158405045139,true,bid,7525.06,0.3028
binance,BTCUSDT,1575158405045139,1575158405045139,true,bid,7525,0.001461
binance,BTCUSDT,1575158405045139,1575158405045139,true,bid,7524.97,0.001329
binance,BTCUSDT,1575158405045139,1575158405045139,true,bid,7524.87,0.001417
binance,BTCUSDT,1575158405045139,1575158405045139,true,bid,7524.75,0.177123
binance,BTCUSDT,1575158405045139,1575158405045139,true,bid,7524.71,0.025356
binance,BTCUSDT,1575158405045139,1575158405045139,true,bid,7524.56,0.001955
binance,BTCUSDT,1575158405045139,1575158405045139,true,bid,7524.17,0.00133
binance,BTCUSDT,1575158405045139,1575158405045139,true,bid,7524.07,0.398203
binance,BTCUSDT,1575158405045139,1575158405045139,true,bid,7524,0.001461
binance,BTCUSDT,1575158405045139,1575158405045139,true,bid,7523.4,0.004539
binance,BTCUSDT,1575158405045139,1575158405045139,true,bid,7523.16,0.0068
binance,BTCUSDT,1575158405045139,1575158405045139,true,bid,7523.08,0.00133
binance,BTCUSDT,1575158405045139,1575158405045139,true,bid,7523,0.267179
binance,BTCUSDT,1575158405045139,1575158405045139,true,bid,7522.58,1.0137
binance,BTCUSDT,1575158405045139,1575158405045139,true,bid,7522.43,0.00133
binance,BTCUSDT,1575158405045139,1575158405045139,true,bid,7522.15,0.001565
binance,BTCUSDT,1575158405045139,1575158405045139,true,bid,7522,0.001462
binance,BTCUSDT,1575158405045139,1575158405045139,true,bid,7521.93,0.002194
binance,BTCUSDT,1575158405045139,1575158405045139,true,bid,7521.9,0.25
binance,BTCUSDT,1575158405045139,1575158405045139,true,bid,7521.8,0.25
binance,BTCUSDT,1575158405045139,1575158405045139,true,bid,7521,0.011559
binance,BTCUSDT,1575158405045139,1575158405045139,true,bid,7520.93,0.00939
binance,BTCUSDT,1575158405045139,1575158405045139,true,bid,7520.4,0.042827
binance,BTCUSDT,1575158405045139,1575158405045139,true,bid,7520.21,0.003888
binance,BTCUSDT,1575158405045139,1575158405045139,true,bid,7520.02,0.058047
binance,BTCUSDT,1575158405045139,1575158405045139,true,bid,7520,0.864213
binance,BTCUSDT,1575158405045139,1575158405045139,true,bid,7519.17,0.00133
binance,BTCUSDT,1575158405045139,1575158405045139,true,bid,7519.13,0.07
binance,BTCUSDT,1575158405045139,1575158405045139,true,bid,7519.11,0.001822
binance,BTCUSDT,1575158405045139,1575158405045139,true,bid,7519,0.001462
binance,BTCUSDT,1575158405045139,1575158405045139,true,bid,7518.98,0.00224
binance,BTCUSDT,1575158405045139,1575158405045139,true,bid,7518.36,0.001804
binance,BTCUSDT,1575158405045139,1575158405045139,true,bid,7518.22,0.48079
binance,BTCUSDT,1575158405045139,1575158405045139,true,bid,7518.14,0.073855
binance,BTCUSDT,1575158405045139,1575158405045139,true,bid,7518,0.395386
binance,BTCUSDT,1575158405045139,1575158405045139,true,bid,7517.97,0.003441
binance,BTCUSDT,1575158405045139,1575158405045139,true,bid,7517.88,0.001331
binance,BTCUSDT,1575158405045139,1575158405045139,true,bid,7517.79,0.002391
binance,BTCUSDT,1575158405045139,1575158405045139,true,bid,7517.04,0.228407
binance,BTCUSDT,1575158405045139,1575158405045139,true,bid,7517.01,0.001331
binance,BTCUSDT,1575158405045139,1575158405045139,true,bid,7517,0.004426
binance,BTCUSDT,1575158405045139,1575158405045139,true,bid,7516.94,0.001331
binance,BTCUSDT,1575158405045139,1575158405045139,true,bid,7516.9,0.25
binance,BTCUSDT,1575158405045139,1575158405045139,true,bid,7516.8,0.25
binance,BTCUSDT,1575158405045139,1575158405045139,true,bid,7516.78,0.001331
binance,BTCUSDT,1575158405045139,1575158405045139,true,bid,7516.57,0.001331
binance,BTCUSDT,1575158405045139,1575158405045139,true,bid,7516.47,0.002056
binance,BTCUSDT,1575158405045139,1575158405045139,true,bid,7516,0.001463
binance,BTCUSDT,1575158405045139,1575158405045139,true,bid,7515.56,0.012257
binance,BTCUSDT,1575158405045139,1575158405045139,true,bid,7515.28,0.039628
binance,BTCUSDT,1575158405045139,1575158405045139,true,bid,7515.18,2.421758
binance,BTCUSDT,1575158405045139,1575158405045139,true,bid,7515,1.505334
binance,BTCUSDT,1575158405045139,1575158405045139,true,bid,7514,0.001463
binance,BTCUSDT,1575158405045139,1575158405045139,true,bid,7513.71,0.00134
binance,BTCUSDT,1575158405045139,1575158405045139,true,bid,7513.51,0.001611
binance,BTCUSDT,1575158405045139,1575158405045139,true,bid,7513.28,0.001515
binance,BTCUSDT,1575158405045139,1575158405045139,true,bid,7513.03,0.001332
binance,BTCUSDT,1575158405045139,1575158405045139,true,bid,7513,0.001464
binance,BTCUSDT,1575158405045139,1575158405045139,true,bid,7512.87,0.001332
binance,BTCUSDT,1575158405045139,1575158405045139,true,bid,7512.82,0.009709
binance,BTCUSDT,1575158405045139,1575158405045139,true,bid,7512,0.011464
binance,BTCUSDT,1575158405045139,1575158405045139,true,bid,7511.9,0.25
binance,BTCUSDT,1575158405045139,1575158405045139,true,bid,7511.45,0.002294
binance,BTCUSDT,1575158405045139,1575158405045139,true,bid,7511.42,0.013519
binance,BTCUSDT,1575158405045139,1575158405045139,true,bid,7511.24,1.647397
binance,BTCUSDT,1575158405045139,1575158405045139,true,bid,7511,0.001464
binance,BTCUSDT,1575158405045139,1575158405045139,true,bid,7510.73,0.029937
binance,BTCUSDT,1575158405045139,1575158405045139,true,bid,7510.15,0.001724
binance,BTCUSDT,1575158405045139,1575158405045139,true,bid,7510,0.461095
binance,BTCUSDT,1575158405045139,1575158405045139,true,bid,7509.24,0.001332
binance,BTCUSDT,1575158405045139,1575158405045139,true,bid,7509.23,0.099358
binance,BTCUSDT,1575158405045139,1575158405045139,true,bid,7509.1,0.001332
binance,BTCUSDT,1575158405045139,1575158405045139,true,bid,7509,0.030942
binance,BTCUSDT,1575158405045139,1575158405045139,true,bid,7508.62,0.179893
binance,BTCUSDT,1575158405045139,1575158405045139,true,bid,7508.31,0.001332
binance,BTCUSDT,1575158405045139,1575158405045139,true,bid,7508,0.001465
binance,BTCUSDT,1575158405045139,1575158405045139,true,bid,7507.69,0.096728
binance,BTCUSDT,1575158405045139,1575158405045139,true,bid,7507.66,0.049341
binance,BTCUSDT,1575158405045139,1575158405045139,true,bid,7507.58,0.003004
binance,BTCUSDT,1575158405045139,1575158405045139,true,bid,7507.5,1.7
binance,BTCUSDT,1575158405045139,1575158405045139,true,bid,7507.21,0.001333
binance,BTCUSDT,1575158405045139,1575158405045139,true,bid,7507.14,0.099407
binance,BTCUSDT,1575158405045139,1575158405045139,true,bid,7507,0.114785
binance,BTCUSDT,1575158405045139,1575158405045139,true,bid,7506.78,1.129855
binance,BTCUSDT,1575158405045139,1575158405045139,true,bid,7506.57,0.001333
binance,BTCUSDT,1575158405045139,1575158405045139,true,bid,7506.32,0.00224
binance,BTCUSDT,1575158405045139,1575158405045139,true,bid,7506.02,0.309553
binance,BTCUSDT,1575158405045139,1575158405045139,true,bid,7506,8.011465
binance,BTCUSDT,1575158405045139,1575158405045139,true,bid,7505.68,0.02
binance,BTCUSDT,1575158405045139,1575158405045139,true,bid,7505.41,0.001463
binance,BTCUSDT,1575158405045139,1575158405045139,true,bid,7505.1,0.042827
binance,BTCUSDT,1575158405045139,1575158405045139,true,bid,7505,0.386953
binance,BTCUSDT,1575158405045139,1575158405045139,true,bid,7504.65,0.00426
binance,BTCUSDT,1575158405045139,1575158405045139,true,bid,7504,0.021465
binance,BTCUSDT,1575158405045139,1575158405045139,true,bid,7503.69,1.011369
binance,BTCUSDT,1575158405045139,1575158405045139,true,bid,7503.28,0.001333
binance,BTCUSDT,1575158405045139,1575158405045139,true,bid,7503.22,0.001443
binance,BTCUSDT,1575158405045139,1575158405045139,true,bid,7503,0.361018
binance,BTCUSDT,1575158405045139,1575158405045139,true,bid,7502.9,0.062104
binance,BTCUSDT,1575158405045139,1575158405045139,true,bid,7502.84,0.039037
binance,BTCUSDT,1575158405045139,1575158405045139,true,bid,7502.3,0.001421
binance,BTCUSDT,1575158405045139,1575158405045139,true,bid,7502,0.152092
binance,BTCUSDT,1575158405045139,1575158405045139,true,bid,7501.99,0.001333
binance,BTCUSDT,1575158405045139,1575158405045139,true,bid,7501.92,0.0558
binance,BTCUSDT,1575158405045139,1575158405045139,true,bid,7501.73,0.019268
binance,BTCUSDT,1575158405045139,1575158405045139,true,bid,7501.22,0.067162
binance,BTCUSDT,1575158405045139,1575158405045139,true,bid,7501.1,3.692486
binance,BTCUSDT,1575158405045139,1575158405045139,true,bid,7501,0.490358
binance,BTCUSDT,1575158405045139,1575158405045139,true,bid,7500.89,0.001334
binance,BTCUSDT,1575158405045139,1575158405045139,true,bid,7500.74,0.004202
binance,BTCUSDT,1575158405045139,1575158405045139,true,bid,7500.68,0.001334
binance,BTCUSDT,1575158405045139,1575158405045139,true,bid,7500.57,0.045227
binance,BTCUSDT,1575158405045139,1575158405045139,true,bid,7500.53,0.001561
binance,BTCUSDT,1575158405045139,1575158405045139,true,bid,7500.15,0.002448
binance,BTCUSDT,1575158405045139,1575158405045139,true,bid,7500.03,8.349518
binance,BTCUSDT,1575158405045139,1575158405045139,true,bid,7500.02,0.004963
binance,BTCUSDT,1575158405045139,1575158405045139,true,bid,7500.01,0.00831
binance,BTCUSDT,1575158405045139,1575158405045139,true,bid,7500,21.500482
binance,BTCUSDT,1575158405045139,1575158405045139,true,bid,7499.33,0.001902
binance,BTCUSDT,1575158405045139,1575158405045139,true,bid,7499.31,0.001466
binance,BTCUSDT,1575158405045139,1575158405045139,true,bid,7498.87,0.285075
binance,BTCUSDT,1575158405045139,1575158405045139,true,bid,7498.56,0.007294
binance,BTCUSDT,1575158405045139,1575158405045139,true,bid,7498.33,0.004143
binance,BTCUSDT,1575158405045139,1575158405045139,true,bid,7498.05,0.008253
binance,BTCUSDT,1575158405045139,1575158405045139,true,bid,7498.04,0.003984
binance,BTCUSDT,1575158405045139,1575158405045139,true,bid,7498,0.028992
binance,BTCUSDT,1575158405045139,1575158405045139,true,bid,7497.95,0.002331
binance,BTCUSDT,1575158405045139,1575158405045139,true,bid,7497.74,0.928931
binance,BTCUSDT,1575158405045139,1575158405045139,true,bid,7497.6,0.003888
binance,BTCUSDT,1575158405045139,1575158405045139,true,bid,7497.38,0.007205
binance,BTCUSDT,1575158405045139,1575158405045139,true,bid,7496.14,1.122444
binance,BTCUSDT,1575158405045139,1575158405045139,true,bid,7496,0.002934
binance,BTCUSDT,1575158405045139,1575158405045139,true,bid,7495.84,0.001783
binance,BTCUSDT,1575158405045139,1575158405045139,true,bid,7495.73,0.0015
binance,BTCUSDT,1575158405045139,1575158405045139,true,bid,7495.49,0.005614
binance,BTCUSDT,1575158405045139,1575158405045139,true,bid,7495.44,0.001488
binance,BTCUSDT,1575158405045139,1575158405045139,true,bid,7495.35,0.001614
binance,BTCUSDT,1575158405045139,1575158405045139,true,bid,7494,0.019034
binance,BTCUSDT,1575158405045139,1575158405045139,true,bid,7493.88,0.001798
binance,BTCUSDT,1575158405045139,1575158405045139,true,bid,7493.67,0.00224
binance,BTCUSDT,1575158405045139,1575158405045139,true,bid,7493.14,0.0015
binance,BTCUSDT,1575158405045139,1575158405045139,true,bid,7493,0.291778
binance,BTCUSDT,1575158405045139,1575158405045139,true,bid,7492.92,0.0186
binance,BTCUSDT,1575158405045139,1575158405045139,true,bid,7492.67,0.025558
binance,BTCUSDT,1575158405045139,1575158405045139,true,bid,7491.4,0.113678
binance,BTCUSDT,1575158405045139,1575158405045139,true,bid,7491.34,0.002649
binance,BTCUSDT,1575158405045139,1575158405045139,true,bid,7491,0.001468
binance,BTCUSDT,1575158405045139,1575158405045139,true,bid,7490.9,0.009273
binance,BTCUSDT,1575158405045139,1575158405045139,true,bid,7490.83,0.467237
binance,BTCUSDT,1575158405045139,1575158405045139,true,bid,7490.82,10.0358
binance,BTCUSDT,1575158405045139,1575158405045139,true,bid,7490.44,0.006004
binance,BTCUSDT,1575158405045139,1575158405045139,true,bid,7490.01,1.832228
binance,BTCUSDT,1575158405045139,1575158405045139,true,bid,7490,0.176418
binance,BTCUSDT,1575158405045139,1575158405045139,true,bid,7489.79,0.044479
binance,BTCUSDT,1575158405045139,1575158405045139,true,bid,7489.59,0.117264
binance,BTCUSDT,1575158405045139,1575158405045139,true,bid,7489.47,0.00156
binance,BTCUSDT,1575158405045139,1575158405045139,true,bid,7489.31,0.049462
binance,BTCUSDT,1575158405045139,1575158405045139,true,bid,7489.28,0.00273
binance,BTCUSDT,1575158405045139,1575158405045139,true,bid,7489.25,0.01009
binance,BTCUSDT,1575158405045139,1575158405045139,true,bid,7489,0.001468
binance,BTCUSDT,1575158405045139,1575158405045139,true,bid,7488.99,0.002016
binance,BTCUSDT,1575158405045139,1575158405045139,true,bid,7488.88,0.0035
binance,BTCUSDT,1575158405045139,1575158405045139,true,bid,7488.64,0.002708
binance,BTCUSDT,1575158405045139,1575158405045139,true,bid,7488,0.022938
binance,BTCUSDT,1575158405045139,1575158405045139,true,bid,7487.6,0.71
binance,BTCUSDT,1575158405045139,1575158405045139,true,bid,7487.17,0.009709
binance,BTCUSDT,1575158405045139,1575158405045139,true,bid,7486.95,0.013356
binance,BTCUSDT,1575158405045139,1575158405045139,true,bid,7486.5,0.013223
binance,BTCUSDT,1575158405045139,1575158405045139,true,bid,7486.44,0.009914
binance,BTCUSDT,1575158405045139,1575158405045139,true,bid,7486.2,0.006
binance,BTCUSDT,1575158405045139,1575158405045139,true,bid,7486,0.002938
binance,BTCUSDT,1575158405045139,1575158405045139,true,bid,7485.88,0.268624
binance,BTCUSDT,1575158405045139,1575158405045139,true,bid,7485.18,0.005342
binance,BTCUSDT,1575158405045139,1575158405045139,true,bid,7485,0.77403
binance,BTCUSDT,1575158405045139,1575158405045139,true,bid,7484.96,0.003563
binance,BTCUSDT,1575158405045139,1575158405045139,true,bid,7484.61,0.096728
binance,BTCUSDT,1575158405045139,1575158405045139,true,bid,7484,0.002938
binance,BTCUSDT,1575158405045139,1575158405045139,true,bid,7483.67,0.66307
binance,BTCUSDT,1575158405045139,1575158405045139,true,bid,7483.04,0.166516
binance,BTCUSDT,1575158405045139,1575158405045139,true,bid,7483,0.001469
binance,BTCUSDT,1575158405045139,1575158405045139,true,bid,7482.78,0.983898
binance,BTCUSDT,1575158405045139,1575158405045139,true,bid,7482.75,0.002373
binance,BTCUSDT,1575158405045139,1575158405045139,true,bid,7482.63,0.00902
binance,BTCUSDT,1575158405045139,1575158405045139,true,bid,7482.21,0.00177
binance,BTCUSDT,1575158405045139,1575158405045139,true,bid,7482,0.025781
binance,BTCUSDT,1575158405045139,1575158405045139,true,bid,7481.98,0.001728
binance,BTCUSDT,1575158405045139,1575158405045139,true,bid,7481.77,0.001482
binance,BTCUSDT,1575158405045139,1575158405045139,true,bid,7481.08,0.002306
binance,BTCUSDT,1575158405045139,1575158405045139,true,bid,7481.01,0.00224
binance,BTCUSDT,1575158405045139,1575158405045139,true,bid,7481,0.036701
binance,BTCUSDT,1575158405045139,1575158405045139,true,bid,7480.15,0.002019
binance,BTCUSDT,1575158405045139,1575158405045139,true,bid,7480.05,0.133689
binance,BTCUSDT,1575158405045139,1575158405045139,true,bid,7480.04,0.003212
binance,BTCUSDT,1575158405045139,1575158405045139,true,bid,7480,24.823096
binance,BTCUSDT,1575158405045139,1575158405045139,true,bid,7479.79,0.001426
binance,BTCUSDT,1575158405045139,1575158405045139,true,bid,7479.73,0.003576
binance,BTCUSDT,1575158405045139,1575158405045139,true,bid,7479.27,0.013256
binance,BTCUSDT,1575158405045139,1575158405045139,true,bid,7479,0.01147
binance,BTCUSDT,1575158405045139,1575158405045139,true,bid,7478.72,0.002483
binance,BTCUSDT,1575158405045139,1575158405045139,true,bid,7478.47,4.168
binance,BTCUSDT,1575158405045139,1575158405045139,true,bid,7478.26,0.001516
binance,BTCUSDT,1575158405045139,1575158405045139,true,bid,7478,0.161074
binance,BTCUSDT,1575158405045139,1575158405045139,true,bid,7477.95,0.007426
binance,BTCUSDT,1575158405045139,1575158405045139,true,bid,7477.88,0.001721
binance,BTCUSDT,1575158405045139,1575158405045139,true,bid,7477.68,0.002391
binance,BTCUSDT,1575158405045139,1575158405045139,true,bid,7477.55,0.001804
binance,BTCUSDT,1575158405045139,1575158405045139,true,bid,7477.26,0.039765
binance,BTCUSDT,1575158405045139,1575158405045139,true,bid,7477.01,0.002407
binance,BTCUSDT,1575158405045139,1575158405045139,true,bid,7477,0.022412
binance,BTCUSDT,1575158405045139,1575158405045139,true,bid,7476.66,0.007053
binance,BTCUSDT,1575158405045139,1575158405045139,true,bid,7476.24,0.007324
binance,BTCUSDT,1575158405045139,1575158405045139,true,bid,7476.16,0.0023
binance,BTCUSDT,1575158405045139,1575158405045139,true,bid,7476.1,0.029937
binance,BTCUSDT,1575158405045139,1575158405045139,true,bid,7476.05,0.002056
binance,BTCUSDT,1575158405045139,1575158405045139,true,bid,7476,0.012942
binance,BTCUSDT,1575158405045139,1575158405045139,true,bid,7475.9,0.001515
binance,BTCUSDT,1575158405045139,1575158405045139,true,bid,7475.48,0.025
binance,BTCUSDT,1575158405045139,1575158405045139,true,bid,7475.09,0.2
binance,BTCUSDT,1575158405045139,1575158405045139,true,bid,7475.02,0.001704
binance,BTCUSDT,1575158405045139,1575158405045139,true,bid,7475,41.123947
binance,BTCUSDT,1575158405045139,1575158405045139,true,bid,7474.98,0.003888
binance,BTCUSDT,1575158405045139,1575158405045139,true,bid,7474.68,0.040149
binance,BTCUSDT,1575158405045139,1575158405045139,true,bid,7474.48,0.042827
binance,BTCUSDT,1575158405045139,1575158405045139,true,bid,7474.46,0.013519
binance,BTCUSDT,1575158405045139,1575158405045139,true,bid,7474.37,0.00134
binance,BTCUSDT,1575158405045139,1575158405045139,true,bid,7474.17,0.189318
binance,BTCUSDT,1575158405045139,1575158405045139,true,bid,7474,0.451011
binance,BTCUSDT,1575158405045139,1575158405045139,true,bid,7473.84,0.001433
binance,BTCUSDT,1575158405045139,1575158405045139,true,bid,7473.76,0.002978
binance,BTCUSDT,1575158405045139,1575158405045139,true,bid,7473.18,0.019161
binance,BTCUSDT,1575158405045139,1575158405045139,true,bid,7473.15,0.006387
binance,BTCUSDT,1575158405045139,1575158405045139,true,bid,7473,0.001471
binance,BTCUSDT,1575158405045139,1575158405045139,true,bid,7472.97,0.001611
binance,BTCUSDT,1575158405045139,1575158405045139,true,bid,7472.8,0.002864
binance,BTCUSDT,1575158405045139,1575158405045139,true,bid,7472.74,0.029956
binance,BTCUSDT,1575158405045139,1575158405045139,true,bid,7472.72,0.1
binance,BTCUSDT,1575158405045139,1575158405045139,true,bid,7472.32,0.005747
binance,BTCUSDT,1575158405045139,1575158405045139,true,bid,7472,1.023947
binance,BTCUSDT,1575158405045139,1575158405045139,true,bid,7471.7,0.026767
binance,BTCUSDT,1575158405045139,1575158405045139,true,bid,7471.51,0.002006
binance,BTCUSDT,1575158405045139,1575158405045139,true,bid,7471.42,0.014736
binance,BTCUSDT,1575158405045139,1575158405045139,true,bid,7471,2.002155
binance,BTCUSDT,1575158405045139,1575158405045139,true,bid,7470.92,3.9718
binance,BTCUSDT,1575158405045139,1575158405045139,true,bid,7470.83,0.026931
binance,BTCUSDT,1575158405045139,1575158405045139,true,bid,7470.82,0.039628
binance,BTCUSDT,1575158405045139,1575158405045139,true,bid,7470.63,0.288083
binance,BTCUSDT,1575158405045139,1575158405045139,true,bid,7470.47,0.043106
binance,BTCUSDT,1575158405045139,1575158405045139,true,bid,7470.45,0.048675
binance,BTCUSDT,1575158405045139,1575158405045139,true,bid,7470.19,0.063351
binance,BTCUSDT,1575158405045139,1575158405045139,true,bid,7470.01,0.005242
binance,BTCUSDT,1575158405045139,1575158405045139,true,bid,7470,6.461022
binance,BTCUSDT,1575158405045139,1575158405045139,true,bid,7469.99,0.007343
binance,BTCUSDT,1575158405045139,1575158405045139,true,bid,7469.84,0.049651
binance,BTCUSDT,1575158405045139,1575158405045139,true,bid,7469.38,0.002092
binance,BTCUSDT,1575158405045139,1575158405045139,true,bid,7469.28,0.0015
binance,BTCUSDT,1575158405045139,1575158405045139,true,bid,7469.2,0.008383
binance,BTCUSDT,1575158405045139,1575158405045139,true,bid,7469,0.001472
binance,BTCUSDT,1575158405045139,1575158405045139,true,bid,7468.73,0.014182
binance,BTCUSDT,1575158405045139,1575158405045139,true,bid,7468.5,0.0496
binance,BTCUSDT,1575158405045139,1575158405045139,true,bid,7468.35,0.00224
binance,BTCUSDT,1575158405045139,1575158405045139,true,bid,7468.33,0.025628
binance,BTCUSDT,1575158405045139,1575158405045139,true,bid,7468.28,0.003108
binance,BTCUSDT,1575158405045139,1575158405045139,true,bid,7468,0.002944
binance,BTCUSDT,1575158405045139,1575158405045139,true,bid,7466.9,0.001473
binance,BTCUSDT,1575158405045139,1575158405045139,true,bid,7466.66,0.003366
binance,BTCUSDT,1575158405045139,1575158405045139,true,bid,7466.6,0.001997
binance,BTCUSDT,1575158405045139,1575158405045139,true,bid,7466.35,0.001516
binance,BTCUSDT,1575158405045139,1575158405045139,true,bid,7466,1.124434
binance,BTCUSDT,1575158405045139,1575158405045139,true,bid,7465.9,0.001473
binance,BTCUSDT,1575158405045139,1575158405045139,true,bid,7465.37,1.031344
binance,BTCUSDT,1575158405045139,1575158405045139,true,bid,7465.18,0.006029
binance,BTCUSDT,1575158405045139,1575158405045139,true,bid,7465.05,0.02345
binance,BTCUSDT,1575158405045139,1575158405045139,true,bid,7465,1.312158
binance,BTCUSDT,1575158405045139,1575158405045139,true,bid,7464.64,0.1
binance,BTCUSDT,1575158405045139,1575158405045139,true,bid,7464.58,0.007743
binance,BTCUSDT,1575158405045139,1575158405045139,true,bid,7464.51,0.001443
binance,BTCUSDT,1575158405045139,1575158405045139,true,bid,7464.46,0.009078
binance,BTCUSDT,1575158405045139,1575158405045139,true,bid,7464.28,0.025
binance,BTCUSDT,1575158405045139,1575158405045139,true,bid,7464.19,0.002064
binance,BTCUSDT,1575158405045139,1575158405045139,true,bid,7464.01,0.006976
binance,BTCUSDT,1575158405045139,1575158405045139,true,bid,7464,0.012946
binance,BTCUSDT,1575158405045139,1575158405045139,true,bid,7463.4,0.019268
binance,BTCUSDT,1575158405045139,1575158405045139,true,bid,7463.06,0.01
binance,BTCUSDT,1575158405045139,1575158405045139,true,bid,7463,0.337082
binance,BTCUSDT,1575158405045139,1575158405045139,true,bid,7462.94,0.249123
binance,BTCUSDT,1575158405045139,1575158405045139,true,bid,7462.85,0.062104
binance,BTCUSDT,1575158405045139,1575158405045139,true,bid,7462.68,0.02
binance,BTCUSDT,1575158405045139,1575158405045139,true,bid,7462.15,0.006037
binance,BTCUSDT,1575158405045139,1575158405045139,true,bid,7462,5.208815
binance,BTCUSDT,1575158405045139,1575158405045139,true,bid,7461.82,0.002679
binance,BTCUSDT,1575158405045139,1575158405045139,true,bid,7461.77,0.0134
binance,BTCUSDT,1575158405045139,1575158405045139,true,bid,7461.76,5.366582
binance,BTCUSDT,1575158405045139,1575158405045139,true,bid,7461.53,0.106437
binance,BTCUSDT,1575158405045139,1575158405045139,true,bid,7461,0.005823
binance,BTCUSDT,1575158405045139,1575158405045139,true,bid,7460.9,0.039037
binance,BTCUSDT,1575158405045139,1575158405045139,true,bid,7460.89,0.017412
binance,BTCUSDT,1575158405045139,1575158405045139,true,bid,7460.84,0.0043
binance,BTCUSDT,1575158405045139,1575158405045139,true,bid,7460.81,0.001497
binance,BTCUSDT,1575158405045139,1575158405045139,true,bid,7460,6.101379
binance,BTCUSDT,1575158405045139,1575158405045139,true,bid,7459.38,0.002126
binance,BTCUSDT,1575158405045139,1575158405045139,true,bid,7459.18,0.042827
binance,BTCUSDT,1575158405045139,1575158405045139,true,bid,7459.03,0.002024
binance,BTCUSDT,1575158405045139,1575158405045139,true,bid,7459,0.001474
binance,BTCUSDT,1575158405045139,1575158405045139,true,bid,7458.33,0.244977
binance,BTCUSDT,1575158405045139,1575158405045139,true,bid,7458.14,0.030626
binance,BTCUSDT,1575158405045139,1575158405045139,true,bid,7458,0.34813
binance,BTCUSDT,1575158405045139,1575158405045139,true,bid,7457.8,0.001987
binance,BTCUSDT,1575158405045139,1575158405045139,true,bid,7457.35,0.00143
binance,BTCUSDT,1575158405045139,1575158405045139,true,bid,7457.09,0.01
binance,BTCUSDT,1575158405045139,1575158405045139,true,bid,7456.63,0.011396
binance,BTCUSDT,1575158405045139,1575158405045139,true,bid,7456,0.340899
binance,BTCUSDT,1575158405045139,1575158405045139,true,bid,7455.69,0.00224
binance,BTCUSDT,1575158405045139,1575158405045139,true,bid,7455.5,6
binance,BTCUSDT,1575158405045139,1575158405045139,true,bid,7455.21,0.052429
binance,BTCUSDT,1575158405045139,1575158405045139,true,bid,7455.18,0.01287
binance,BTCUSDT,1575158405045139,1575158405045139,true,bid,7455.09,0.2
binance,BTCUSDT,1575158405045139,1575158405045139,true,bid,7455.08,0.04248
binance,BTCUSDT,1575158405045139,1575158405045139,true,bid,7455.05,0.1
binance,BTCUSDT,1575158405045139,1575158405045139,true,bid,7455,0.026274
binance,BTCUSDT,1575158405045139,1575158405045139,true,bid,7454.58,0.014037
binance,BTCUSDT,1575158405045139,1575158405045139,true,bid,7454,0.001475
binance,BTCUSDT,1575158405045139,1575158405045139,true,bid,7453.49,0.007294
binance,BTCUSDT,1575158405045139,1575158405045139,true,bid,7453.41,0.02643
binance,BTCUSDT,1575158405045139,1575158405045139,true,bid,7453.37,0.067162
binance,BTCUSDT,1575158405045139,1575158405045139,true,bid,7453,0.00295
binance,BTCUSDT,1575158405045139,1575158405045139,true,bid,7452.98,0.001891
binance,BTCUSDT,1575158405045139,1575158405045139,true,bid,7452.88,0.004143
binance,BTCUSDT,1575158405045139,1575158405045139,true,bid,7452.79,0.001466
binance,BTCUSDT,1575158405045139,1575158405045139,true,bid,7452.62,0.004012
binance,BTCUSDT,1575158405045139,1575158405045139,true,bid,7452.53,0.103439
binance,BTCUSDT,1575158405045139,1575158405045139,true,bid,7452.48,0.004468
binance,BTCUSDT,1575158405045139,1575158405045139,true,bid,7452.36,0.003888
binance,BTCUSDT,1575158405045139,1575158405045139,true,bid,7452.17,0.028455
binance,BTCUSDT,1575158405045139,1575158405045139,true,bid,7452.08,0.021
binance,BTCUSDT,1575158405045139,1575158405045139,true,bid,7452.06,0.002546
binance,BTCUSDT,1575158405045139,1575158405045139,true,bid,7452,0.083448
binance,BTCUSDT,1575158405045139,1575158405045139,true,bid,7451.78,0.012106
binance,BTCUSDT,1575158405045139,1575158405045139,true,bid,7451.33,0.0023
binance,BTCUSDT,1575158405045139,1575158405045139,true,bid,7451.03,0.455725
binance,BTCUSDT,1575158405045139,1575158405045139,true,bid,7451,1.138932
binance,BTCUSDT,1575158405045139,1575158405045139,true,bid,7450.9,0.001411
binance,BTCUSDT,1575158405045139,1575158405045139,true,bid,7450.66,0.002649
binance,BTCUSDT,1575158405045139,1575158405045139,true,bid,7450.02,0.281
binance,BTCUSDT,1575158405045139,1575158405045139,true,bid,7450.01,0.004051
binance,BTCUSDT,1575158405045139,1575158405045139,true,bid,7450,24.661392
binance,BTCUSDT,1575158405045139,1575158405045139,true,bid,7449.95,0.094989
binance,BTCUSDT,1575158405045139,1575158405045139,true,bid,7449.88,0.018781
binance,BTCUSDT,1575158405045139,1575158405045139,true,bid,7449.43,0.00273
binance,BTCUSDT,1575158405045139,1575158405045139,true,bid,7449.09,0.013411
binance,BTCUSDT,1575158405045139,1575158405045139,true,bid,7449,0.001476
binance,BTCUSDT,1575158405045139,1575158405045139,true,bid,7448.89,0.007205
binance,BTCUSDT,1575158405045139,1575158405045139,true,bid,7448.81,0.002708
binance,BTCUSDT,1575158405045139,1575158405045139,true,bid,7448.74,0.002682
binance,BTCUSDT,1575158405045139,1575158405045139,true,bid,7448.58,0.001457
binance,BTCUSDT,1575158405045139,1575158405045139,true,bid,7448,0.002952
binance,BTCUSDT,1575158405045139,1575158405045139,true,bid,7447.99,0.024657
binance,BTCUSDT,1575158405045139,1575158405045139,true,bid,7447.57,0.0075
binance,BTCUSDT,1575158405045139,1575158405045139,true,bid,7447.43,0.001665
binance,BTCUSDT,1575158405045139,1575158405045139,true,bid,7447.01,0.003222
binance,BTCUSDT,1575158405045139,1575158405045139,true,bid,7447,0.114409
binance,BTCUSDT,1575158405045139,1575158405045139,true,bid,7446.97,0.004841
binance,BTCUSDT,1575158405045139,1575158405045139,true,bid,7446.9,0.001477
binance,BTCUSDT,1575158405045139,1575158405045139,true,bid,7446.86,0.001356
binance,BTCUSDT,1575158405045139,1575158405045139,true,bid,7446.72,0.010735
binance,BTCUSDT,1575158405045139,1575158405045139,true,bid,7446.54,0.001784
binance,BTCUSDT,1575158405045139,1575158405045139,true,bid,7446.09,0.001475
binance,BTCUSDT,1575158405045139,1575158405045139,true,bid,7446,0.220746
binance,BTCUSDT,1575158405045139,1575158405045139,true,bid,7445.91,0.001799
binance,BTCUSDT,1575158405045139,1575158405045139,true,bid,7445.45,0.009273
binance,BTCUSDT,1575158405045139,1575158405045139,true,bid,7445.42,0.0015
binance,BTCUSDT,1575158405045139,1575158405045139,true,bid,7445.37,0.005502
binance,BTCUSDT,1575158405045139,1575158405045139,true,bid,7445.35,0.013431
binance,BTCUSDT,1575158405045139,1575158405045139,true,bid,7445.24,0.343542
binance,BTCUSDT,1575158405045139,1575158405045139,true,bid,7445.01,0.056438
binance,BTCUSDT,1575158405045139,1575158405045139,true,bid,7445,0.538847
binance,BTCUSDT,1575158405045139,1575158405045139,true,bid,7444.89,0.002331
binance,BTCUSDT,1575158405045139,1575158405045139,true,bid,7444.83,0.117264
binance,BTCUSDT,1575158405045139,1575158405045139,true,bid,7444.75,0.01327
binance,BTCUSDT,1575158405045139,1575158405045139,true,bid,7444.73,0.119421
binance,BTCUSDT,1575158405045139,1575158405045139,true,bid,7444.49,0.029009
binance,BTCUSDT,1575158405045139,1575158405045139,true,bid,7444.44,0.026865
binance,BTCUSDT,1575158405045139,1575158405045139,true,bid,7444.38,0.00289
binance,BTCUSDT,1575158405045139,1575158405045139,true,bid,7444.32,8.136
binance,BTCUSDT,1575158405045139,1575158405045139,true,bid,7444.2,0.001578
binance,BTCUSDT,1575158405045139,1575158405045139,true,bid,7444.12,0.001344
binance,BTCUSDT,1575158405045139,1575158405045139,true,bid,7444.06,0.009914
binance,BTCUSDT,1575158405045139,1575158405045139,true,bid,7444.04,0.2
binance,BTCUSDT,1575158405045139,1575158405045139,true,bid,7444,0.024523
binance,BTCUSDT,1575158405045139,1575158405045139,true,bid,7443.95,0.0018
binance,BTCUSDT,1575158405045139,1575158405045139,true,bid,7443.87,0.042827
binance,BTCUSDT,1575158405045139,1575158405045139,true,bid,7443.81,0.101771
binance,BTCUSDT,1575158405045139,1575158405045139,true,bid,7443.62,0.294438
binance,BTCUSDT,1575158405045139,1575158405045139,true,bid,7443.48,0.012906
binance,BTCUSDT,1575158405045139,1575158405045139,true,bid,7443.22,0.14028
binance,BTCUSDT,1575158405045139,1575158405045139,true,bid,7443.12,0.001478
binance,BTCUSDT,1575158405045139,1575158405045139,true,bid,7443.03,0.004933
binance,BTCUSDT,1575158405045139,1575158405045139,true,bid,7443,0.001477
binance,BTCUSDT,1575158405045139,1575158405045139,true,bid,7442.85,0.012554
binance,BTCUSDT,1575158405045139,1575158405045139,true,bid,7442.83,0.006577
binance,BTCUSDT,1575158405045139,1575158405045139,true,bid,7442.65,0.023438
binance,BTCUSDT,1575158405045139,1575158405045139,true,bid,7442.1,0.00156
binance,BTCUSDT,1575158405045139,1575158405045139,true,bid,7442,0.246252
binance,BTCUSDT,1575158405045139,1575158405045139,true,bid,7441.66,0.001534
binance,BTCUSDT,1575158405045139,1575158405045139,true,bid,7441.26,0.040816
binance,BTCUSDT,1575158405045139,1575158405045139,true,bid,7441.17,0.001488
binance,BTCUSDT,1575158405045139,1575158405045139,true,bid,7441.01,0.005037
binance,BTCUSDT,1575158405045139,1575158405045139,true,bid,7441,3.547974
binance,BTCUSDT,1575158405045139,1575158405045139,true,bid,7440.96,0.080913
binance,BTCUSDT,1575158405045139,1575158405045139,true,bid,7440.92,0.012136
binance,BTCUSDT,1575158405045139,1575158405045139,true,bid,7440.52,0.001902
binance,BTCUSDT,1575158405045139,1575158405045139,true,bid,7440.09,0.2
binance,BTCUSDT,1575158405045139,1575158405045139,true,bid,7440.02,0.001516
binance,BTCUSDT,1575158405045139,1575158405045139,true,bid,7440,11.100706
binance,BTCUSDT,1575158405045139,1575158405045139,true,bid,7439.28,0.039839
binance,BTCUSDT,1575158405045139,1575158405045139,true,bid,7439.21,0.004741
binance,BTCUSDT,1575158405045139,1575158405045139,true,bid,7439.06,0.001783
binance,BTCUSDT,1575158405045139,1575158405045139,true,bid,7439,0.001478
binance,BTCUSDT,1575158405045139,1575158405045139,true,bid,7438.91,0.221806
binance,BTCUSDT,1575158405045139,1575158405045139,true,bid,7438.7,0.001505
binance,BTCUSDT,1575158405045139,1575158405045139,true,bid,7438.51,0.026341
binance,BTCUSDT,1575158405045139,1575158405045139,true,bid,7438.46,0.096728
binance,BTCUSDT,1575158405045139,1575158405045139,true,bid,7438.37,0.232115
binance,BTCUSDT,1575158405045139,1575158405045139,true,bid,7438.33,3.9226
binance,BTCUSDT,1575158405045139,1575158405045139,true,bid,7438.28,0.044217
binance,BTCUSDT,1575158405045139,1575158405045139,true,bid,7438.2,0.002017
binance,BTCUSDT,1575158405045139,1575158405045139,true,bid,7438.16,0.047762
binance,BTCUSDT,1575158405045139,1575158405045139,true,bid,7438,0.234478
binance,BTCUSDT,1575158405045139,1575158405045139,true,bid,7437.91,0.001478
binance,BTCUSDT,1575158405045139,1575158405045139,true,bid,7437.7,0.0015
binance,BTCUSDT,1575158405045139,1575158405045139,true,bid,7437.65,0.002239
binance,BTCUSDT,1575158405045139,1575158405045139,true,bid,7437.63,0.064993
binance,BTCUSDT,1575158405045139,1575158405045139,true,bid,7437.57,0.002391
binance,BTCUSDT,1575158405045139,1575158405045139,true,bid,7437.5,0.035449
binance,BTCUSDT,1575158405045139,1575158405045139,true,bid,7437.49,0.030679
binance,BTCUSDT,1575158405045139,1575158405045139,true,bid,7437.46,0.011065
binance,BTCUSDT,1575158405045139,1575158405045139,true,bid,7437.41,0.001457
binance,BTCUSDT,1575158405045139,1575158405045139,true,bid,7437.31,5.082487
binance,BTCUSDT,1575158405045139,1575158405045139,true,bid,7437,0.001479
binance,BTCUSDT,1575158405045139,1575158405045139,true,bid,7436.97,0.03
binance,BTCUSDT,1575158405045139,1575158405045139,true,bid,7436.95,0.002958
binance,BTCUSDT,1575158405045139,1575158405045139,true,bid,7436.89,0.00298
binance,BTCUSDT,1575158405045139,1575158405045139,true,bid,7436.78,0.002373
binance,BTCUSDT,1575158405045139,1575158405045139,true,bid,7436.73,0.001804
binance,BTCUSDT,1575158405045139,1575158405045139,true,bid,7436.66,0.003042
binance,BTCUSDT,1575158405045139,1575158405045139,true,bid,7436.5,0.002383
binance,BTCUSDT,1575158405045139,1575158405045139,true,bid,7436.34,0.003563
binance,BTCUSDT,1575158405045139,1575158405045139,true,bid,7436,0.112867
binance,BTCUSDT,1575158405045139,1575158405045139,true,bid,7435.89,0.009709
binance,BTCUSDT,1575158405045139,1575158405045139,true,bid,7435.63,0.002056
binance,BTCUSDT,1575158405045139,1575158405045139,true,bid,7435.4,0.040064
binance,BTCUSDT,1575158405045139,1575158405045139,true,bid,7435.01,0.036308
binance,BTCUSDT,1575158405045139,1575158405045139,true,bid,7435,1.474825
binance,BTCUSDT,1575158405045139,1575158405045139,true,bid,7434.98,0.001434
binance,BTCUSDT,1575158405045139,1575158405045139,true,bid,7434.89,0.065045
binance,BTCUSDT,1575158405045139,1575158405045139,true,bid,7434.78,0.009141
binance,BTCUSDT,1575158405045139,1575158405045139,true,bid,7434.55,0.005639
binance,BTCUSDT,1575158405045139,1575158405045139,true,bid,7434.52,0.001652
binance,BTCUSDT,1575158405045139,1575158405045139,true,bid,7434.12,0.001614
binance,BTCUSDT,1575158405045139,1575158405045139,true,bid,7434,0.09844
binance,BTCUSDT,1575158405045139,1575158405045139,true,bid,7433.85,0.013452
binance,BTCUSDT,1575158405045139,1575158405045139,true,bid,7433.79,0.003049
binance,BTCUSDT,1575158405045139,1575158405045139,true,bid,7433.61,0.053809
binance,BTCUSDT,1575158405045139,1575158405045139,true,bid,7433.56,0.1
binance,BTCUSDT,1575158405045139,1575158405045139,true,bid,7433.45,0.036406
binance,BTCUSDT,1575158405045139,1575158405045139,true,bid,7433,0.08296
binance,BTCUSDT,1575158405045139,1575158405045139,true,bid,7432.56,0.695416
binance,BTCUSDT,1575158405045139,1575158405045139,true,bid,7432.43,0.001611
binance,BTCUSDT,1575158405045139,1575158405045139,true,bid,7432.39,0.00235
binance,BTCUSDT,1575158405045139,1575158405045139,true,bid,7432.08,0.003204
binance,BTCUSDT,1575158405045139,1575158405045139,true,bid,7432,1.95815
binance,BTCUSDT,1575158405045139,1575158405045139,true,bid,7431.96,0.001889
binance,BTCUSDT,1575158405045139,1575158405045139,true,bid,7431.41,0.803462
binance,BTCUSDT,1575158405045139,1575158405045139,true,bid,7431.3,0.089465
binance,BTCUSDT,1575158405045139,1575158405045139,true,bid,7431.14,0.024325
binance,BTCUSDT,1575158405045139,1575158405045139,true,bid,7431.11,0.009447
binance,BTCUSDT,1575158405045139,1575158405045139,true,bid,7431,0.261704
binance,BTCUSDT,1575158405045139,1575158405045139,true,bid,7430.93,0.125775
binance,BTCUSDT,1575158405045139,1575158405045139,true,bid,7430.83,0.012682
binance,BTCUSDT,1575158405045139,1575158405045139,true,bid,7430.8,0.013458
binance,BTCUSDT,1575158405045139,1575158405045139,true,bid,7430.77,0.001704
binance,BTCUSDT,1575158405045139,1575158405045139,true,bid,7430.37,0.042389
binance,BTCUSDT,1575158405045139,1575158405045139,true,bid,7430.09,0.2
binance,BTCUSDT,1575158405045139,1575158405045139,true,bid,7430.05,0.00798
binance,BTCUSDT,1575158405045139,1575158405045139,true,bid,7430,39.688023
binance,BTCUSDT,1575158405045139,1575158405045139,true,bid,7429.95,0.013171
binance,BTCUSDT,1575158405045139,1575158405045139,true,bid,7429.74,0.003888
binance,BTCUSDT,1575158405045139,1575158405045139,true,bid,7429.71,0.032008
binance,BTCUSDT,1575158405045139,1575158405045139,true,bid,7429.69,0.208
binance,BTCUSDT,1575158405045139,1575158405045139,true,bid,7429.64,2.5085
binance,BTCUSDT,1575158405045139,1575158405045139,true,bid,7429.21,0.010013
binance,BTCUSDT,1575158405045139,1575158405045139,true,bid,7429.2,0.001731
binance,BTCUSDT,1575158405045139,1575158405045139,true,bid,7429.19,0.002032
binance,BTCUSDT,1575158405045139,1575158405045139,true,bid,7429.09,0.002947
binance,BTCUSDT,1575158405045139,1575158405045139,true,bid,7429.02,0.026921
binance,BTCUSDT,1575158405045139,1575158405045139,true,bid,7429,0.046851
binance,BTCUSDT,1575158405045139,1575158405045139,true,bid,7428.97,0.002085
binance,BTCUSDT,1575158405045139,1575158405045139,true,bid,7428.57,0.044479
binance,BTCUSDT,1575158405045139,1575158405045139,true,bid,7428.33,10.050804
binance,BTCUSDT,1575158405045139,1575158405045139,true,bid,7428.27,0.014143
binance,BTCUSDT,1575158405045139,1575158405045139,true,bid,7428.2,0.001597
binance,BTCUSDT,1575158405045139,1575158405045139,true,bid,7428.16,0.002
binance,BTCUSDT,1575158405045139,1575158405045139,true,bid,7428,0.480584
binance,BTCUSDT,1575158405045139,1575158405045139,true,bid,7427.36,0.00177
binance,BTCUSDT,1575158405045139,1575158405045139,true,bid,7427.27,0.1
binance,BTCUSDT,1575158405045139,1575158405045139,true,bid,7427,0.763721
binance,BTCUSDT,1575158405045139,1575158405045139,true,bid,7426.91,0.101134
binance,BTCUSDT,1575158405045139,1575158405045139,true,bid,7426.76,0.129737
binance,BTCUSDT,1575158405045139,1575158405045139,true,bid,7426.63,0.039628
binance,BTCUSDT,1575158405045139,1575158405045139,true,bid,7426.54,0.2141
binance,BTCUSDT,1575158405045139,1575158405045139,true,bid,7426.5,0.0023
binance,BTCUSDT,1575158405045139,1575158405045139,true,bid,7426.49,0.004472
binance,BTCUSDT,1575158405045139,1575158405045139,true,bid,7426.25,0.011089
binance,BTCUSDT,1575158405045139,1575158405045139,true,bid,7426.2,0.179714
binance,BTCUSDT,1575158405045139,1575158405045139,true,bid,7426,1.173489
binance,BTCUSDT,1575158405045139,1575158405045139,true,bid,7425.95,0.001465
binance,BTCUSDT,1575158405045139,1575158405045139,true,bid,7425.8,0.001443
binance,BTCUSDT,1575158405045139,1575158405045139,true,bid,7425.74,2.346018
binance,BTCUSDT,1575158405045139,1575158405045139,true,bid,7425.26,0.213004
binance,BTCUSDT,1575158405045139,1575158405045139,true,bid,7425.15,0.146214
binance,BTCUSDT,1575158405045139,1575158405045139,true,bid,7425.12,0.526817
binance,BTCUSDT,1575158405045139,1575158405045139,true,bid,7425.07,0.019268
binance,BTCUSDT,1575158405045139,1575158405045139,true,bid,7425,6.22953
binance,BTCUSDT,1575158405045139,1575158405045139,true,bid,7424.99,0.004707
binance,BTCUSDT,1575158405045139,1575158405045139,true,bid,7424.88,0.004908
binance,BTCUSDT,1575158405045139,1575158405045139,true,bid,7424.79,0.001972
binance,BTCUSDT,1575158405045139,1575158405045139,true,bid,7424.78,0.011484
binance,BTCUSDT,1575158405045139,1575158405045139,true,bid,7424.68,0.162158
binance,BTCUSDT,1575158405045139,1575158405045139,true,bid,7424.56,0.089456
binance,BTCUSDT,1575158405045139,1575158405045139,true,bid,7424.29,0.381112
binance,BTCUSDT,1575158405045139,1575158405045139,true,bid,7424.2,0.010061
binance,BTCUSDT,1575158405045139,1575158405045139,true,bid,7424.11,0.048675
binance,BTCUSDT,1575158405045139,1575158405045139,true,bid,7424.03,0.002328
binance,BTCUSDT,1575158405045139,1575158405045139,true,bid,7424,0.03
binance,BTCUSDT,1575158405045139,1575158405045139,true,bid,7423.72,0.001985
binance,BTCUSDT,1575158405045139,1575158405045139,true,bid,7423.5,0.006601
binance,BTCUSDT,1575158405045139,1575158405045139,true,bid,7423,1.281899
binance,BTCUSDT,1575158405045139,1575158405045139,true,bid,7422.8,0.062104
binance,BTCUSDT,1575158405045139,1575158405045139,true,bid,7422.36,0.001357
binance,BTCUSDT,1575158405045139,1575158405045139,true,bid,7422.2,0.080967
binance,BTCUSDT,1575158405045139,1575158405045139,true,bid,7422,20.388625
binance,BTCUSDT,1575158405045139,1575158405045139,true,bid,7421.92,0.001496
binance,BTCUSDT,1575158405045139,1575158405045139,true,bid,7421.57,0.0015
binance,BTCUSDT,1575158405045139,1575158405045139,true,bid,7421.01,0.014686
binance,BTCUSDT,1575158405045139,1575158405045139,true,bid,7421,0.271197
binance,BTCUSDT,1575158405045139,1575158405045139,true,bid,7420.98,0.126314
binance,BTCUSDT,1575158405045139,1575158405045139,true,bid,7420.92,0.045856
binance,BTCUSDT,1575158405045139,1575158405045139,true,bid,7420.82,0.010474
binance,BTCUSDT,1575158405045139,1575158405045139,true,bid,7420.5,0.005326
binance,BTCUSDT,1575158405045139,1575158405045139,true,bid,7420.47,0.006387
binance,BTCUSDT,1575158405045139,1575158405045139,true,bid,7420.34,0.001575
binance,BTCUSDT,1575158405045139,1575158405045139,true,bid,7420.09,0.2
binance,BTCUSDT,1575158405045139,1575158405045139,true,bid,7420,15.38529
binance,BTCUSDT,1575158405045139,1575158405045139,true,bid,7419.93,0.003576
binance,BTCUSDT,1575158405045139,1575158405045139,true,bid,7419.51,0.08
binance,BTCUSDT,1575158405045139,1575158405045139,true,bid,7419.12,0.04
binance,BTCUSDT,1575158405045139,1575158405045139,true,bid,7419.01,0.01114
binance,BTCUSDT,1575158405045139,1575158405045139,true,bid,7419,0.592281
binance,BTCUSDT,1575158405045139,1575158405045139,true,bid,7418.97,0.039037
binance,BTCUSDT,1575158405045139,1575158405045139,true,bid,7418.94,0.00246
binance,BTCUSDT,1575158405045139,1575158405045139,true,bid,7418.73,0.0168
binance,BTCUSDT,1575158405045139,1575158405045139,true,bid,7418.41,0.040439
binance,BTCUSDT,1575158405045139,1575158405045139,true,bid,7418.4,0.103662
binance,BTCUSDT,1575158405045139,1575158405045139,true,bid,7418,0.314715
binance,BTCUSDT,1575158405045139,1575158405045139,true,bid,7417.72,0.00224
binance,BTCUSDT,1575158405045139,1575158405045139,true,bid,7417.68,0.091246
binance,BTCUSDT,1575158405045139,1575158405045139,true,bid,7417.42,0.002696
binance,BTCUSDT,1575158405045139,1575158405045139,true,bid,7417.15,0.001752
binance,BTCUSDT,1575158405045139,1575158405045139,true,bid,7417.04,0.065133
binance,BTCUSDT,1575158405045139,1575158405045139,true,bid,7417,0.162521
binance,BTCUSDT,1575158405045139,1575158405045139,true,bid,7416.66,0.982521
binance,BTCUSDT,1575158405045139,1575158405045139,true,bid,7416.23,0.070516
binance,BTCUSDT,1575158405045139,1575158405045139,true,bid,7416.21,0.067837
binance,BTCUSDT,1575158405045139,1575158405045139,true,bid,7416.18,0.002146
binance,BTCUSDT,1575158405045139,1575158405045139,true,bid,7416.16,0.120727
binance,BTCUSDT,1575158405045139,1575158405045139,true,bid,7416,0.016832
binance,BTCUSDT,1575158405045139,1575158405045139,true,bid,7415.79,0.001475
binance,BTCUSDT,1575158405045139,1575158405045139,true,bid,7415.76,0.105003
binance,BTCUSDT,1575158405045139,1575158405045139,true,bid,7415.75,3.75
binance,BTCUSDT,1575158405045139,1575158405045139,true,bid,7415.73,0.006187
binance,BTCUSDT,1575158405045139,1575158405045139,true,bid,7415.68,0.003351
binance,BTCUSDT,1575158405045139,1575158405045139,true,bid,7415.65,0.001349
binance,BTCUSDT,1575158405045139,1575158405045139,true,bid,7415.38,0.096728
binance,BTCUSDT,1575158405045139,1575158405045139,true,bid,7415.31,0.009035
binance,BTCUSDT,1575158405045139,1575158405045139,true,bid,7415.21,0.001349
binance,BTCUSDT,1575158405045139,1575158405045139,true,bid,7415.12,0.001457
binance,BTCUSDT,1575158405045139,1575158405045139,true,bid,7415.08,0.066925
binance,BTCUSDT,1575158405045139,1575158405045139,true,bid,7415,4.095211
binance,BTCUSDT,1575158405045139,1575158405045139,true,bid,7414.9,0.027377
binance,BTCUSDT,1575158405045139,1575158405045139,true,bid,7414.85,0.002358
binance,BTCUSDT,1575158405045139,1575158405045139,true,bid,7414.6,0.001349
binance,BTCUSDT,1575158405045139,1575158405045139,true,bid,7414.58,0.0112
binance,BTCUSDT,1575158405045139,1575158405045139,true,bid,7414.43,0.005747
binance,BTCUSDT,1575158405045139,1575158405045139,true,bid,7414.28,0.00143
binance,BTCUSDT,1575158405045139,1575158405045139,true,bid,7414.19,0.148365
binance,BTCUSDT,1575158405045139,1575158405045139,true,bid,7414.14,0.001796
binance,BTCUSDT,1575158405045139,1575158405045139,true,bid,7414.01,0.29327
binance,BTCUSDT,1575158405045139,1575158405045139,true,bid,7414,0.563338
binance,BTCUSDT,1575158405045139,1575158405045139,true,bid,7413.79,0.001599
binance,BTCUSDT,1575158405045139,1575158405045139,true,bid,7413.26,0.042827
binance,BTCUSDT,1575158405045139,1575158405045139,true,bid,7413,8.309191
binance,BTCUSDT,1575158405045139,1575158405045139,true,bid,7412.9,0.02
binance,BTCUSDT,1575158405045139,1575158405045139,true,bid,7412.67,0.001438
binance,BTCUSDT,1575158405045139,1575158405045139,true,bid,7412.58,0.028075
binance,BTCUSDT,1575158405045139,1575158405045139,true,bid,7412.5,0.15507
binance,BTCUSDT,1575158405045139,1575158405045139,true,bid,7412.37,0.01
binance,BTCUSDT,1575158405045139,1575158405045139,true,bid,7412.35,0.002341
binance,BTCUSDT,1575158405045139,1575158405045139,true,bid,7412.31,0.006746
binance,BTCUSDT,1575158405045139,1575158405045139,true,bid,7412.2,2.326
binance,BTCUSDT,1575158405045139,1575158405045139,true,bid,7412.15,0.197623
binance,BTCUSDT,1575158405045139,1575158405045139,true,bid,7412.09,0.003
binance,BTCUSDT,1575158405045139,1575158405045139,true,bid,7412.04,0.02
binance,BTCUSDT,1575158405045139,1575158405045139,true,bid,7412.01,0.01882
binance,BTCUSDT,1575158405045139,1575158405045139,true,bid,7412,14.319842
binance,BTCUSDT,1575158405045139,1575158405045139,true,bid,7411.85,0.008096
binance,BTCUSDT,1575158405045139,1575158405045139,true,bid,7411.72,0.007237
binance,BTCUSDT,1575158405045139,1575158405045139,true,bid,7411.11,0.025
binance,BTCUSDT,1575158405045139,1575158405045139,true,bid,7411.1,0.235173
binance,BTCUSDT,1575158405045139,1575158405045139,true,bid,7411,6.393101
binance,BTCUSDT,1575158405045139,1575158405045139,true,bid,7410.65,0.203892
binance,BTCUSDT,1575158405045139,1575158405045139,true,bid,7410.61,0.001722
binance,BTCUSDT,1575158405045139,1575158405045139,true,bid,7410.54,0.02
binance,BTCUSDT,1575158405045139,1575158405045139,true,bid,7410.25,0.009709
binance,BTCUSDT,1575158405045139,1575158405045139,true,bid,7410.16,12.098
binance,BTCUSDT,1575158405045139,1575158405045139,true,bid,7410.09,0.201721
binance,BTCUSDT,1575158405045139,1575158405045139,true,bid,7410.08,0.093521
binance,BTCUSDT,1575158405045139,1575158405045139,true,bid,7410.03,0.04008
binance,BTCUSDT,1575158405045139,1575158405045139,true,bid,7410,13.444703
binance,BTCUSDT,1575158405045139,1575158405045139,true,bid,7409.98,0.002649
binance,BTCUSDT,1575158405045139,1575158405045139,true,bid,7409.57,0.00273
binance,BTCUSDT,1575158405045139,1575158405045139,true,bid,7409.3,0.269931
binance,BTCUSDT,1575158405045139,1575158405045139,true,bid,7409,0.001484
binance,BTCUSDT,1575158405045139,1575158405045139,true,bid,7408.98,0.002708
binance,BTCUSDT,1575158405045139,1575158405045139,true,bid,7408.82,0.011
binance,BTCUSDT,1575158405045139,1575158405045139,true,bid,7408.75,0.041264
binance,BTCUSDT,1575158405045139,1575158405045139,true,bid,7408.43,0.007294
binance,BTCUSDT,1575158405045139,1575158405045139,true,bid,7408.3,0.017548
binance,BTCUSDT,1575158405045139,1575158405045139,true,bid,7408.22,0.02
binance,BTCUSDT,1575158405045139,1575158405045139,true,bid,7408.2,0.001586
binance,BTCUSDT,1575158405045139,1575158405045139,true,bid,7408.18,0.036507
binance,BTCUSDT,1575158405045139,1575158405045139,true,bid,7408.16,0.002092
binance,BTCUSDT,1575158405045139,1575158405045139,true,bid,7408,68.900992
binance,BTCUSDT,1575158405045139,1575158405045139,true,bid,7407.88,0.182571
binance,BTCUSDT,1575158405045139,1575158405045139,true,bid,7407.87,0.002751
binance,BTCUSDT,1575158405045139,1575158405045139,true,bid,7407.43,0.004143
binance,BTCUSDT,1575158405045139,1575158405045139,true,bid,7407.39,0.001539
binance,BTCUSDT,1575158405045139,1575158405045139,true,bid,7407.22,0.002002
binance,BTCUSDT,1575158405045139,1575158405045139,true,bid,7407.14,0.0082
binance,BTCUSDT,1575158405045139,1575158405045139,true,bid,7407.13,0.25
binance,BTCUSDT,1575158405045139,1575158405045139,true,bid,7407.12,0.003888
binance,BTCUSDT,1575158405045139,1575158405045139,true,bid,7407.1,0.001485
binance,BTCUSDT,1575158405045139,1575158405045139,true,bid,7407.07,0.416861
binance,BTCUSDT,1575158405045139,1575158405045139,true,bid,7407,0.34555
binance,BTCUSDT,1575158405045139,1575158405045139,true,bid,7406.92,0.015
binance,BTCUSDT,1575158405045139,1575158405045139,true,bid,7406.56,0.001466
binance,BTCUSDT,1575158405045139,1575158405045139,true,bid,7406.32,0.012746
binance,BTCUSDT,1575158405045139,1575158405045139,true,bid,7406,0.923376
binance,BTCUSDT,1575158405045139,1575158405045139,true,bid,7405.82,0.067162
binance,BTCUSDT,1575158405045139,1575158405045139,true,bid,7405.66,0.001636
binance,BTCUSDT,1575158405045139,1575158405045139,true,bid,7405.59,0.081959
binance,BTCUSDT,1575158405045139,1575158405045139,true,bid,7405.29,1.742229
binance,BTCUSDT,1575158405045139,1575158405045139,true,bid,7405.28,0.36222
binance,BTCUSDT,1575158405045139,1575158405045139,true,bid,7405.08,0.002032
binance,BTCUSDT,1575158405045139,1575158405045139,true,bid,7405.06,0.00224
binance,BTCUSDT,1575158405045139,1575158405045139,true,bid,7405,5.897759
binance,BTCUSDT,1575158405045139,1575158405045139,true,bid,7404.36,4.461196
binance,BTCUSDT,1575158405045139,1575158405045139,true,bid,7404.28,0.006752
binance,BTCUSDT,1575158405045139,1575158405045139,true,bid,7404.01,0.009143
binance,BTCUSDT,1575158405045139,1575158405045139,true,bid,7404,0.01297
binance,BTCUSDT,1575158405045139,1575158405045139,true,bid,7403.99,0.001457
binance,BTCUSDT,1575158405045139,1575158405045139,true,bid,7403.46,0.10386
binance,BTCUSDT,1575158405045139,1575158405045139,true,bid,7403.45,0.005781
binance,BTCUSDT,1575158405045139,1575158405045139,true,bid,7403,2.907111
binance,BTCUSDT,1575158405045139,1575158405045139,true,bid,7402.96,0.368657
binance,BTCUSDT,1575158405045139,1575158405045139,true,bid,7402.58,0.016663
binance,BTCUSDT,1575158405045139,1575158405045139,true,bid,7402.35,0.010796
binance,BTCUSDT,1575158405045139,1575158405045139,true,bid,7402.18,2.748308
binance,BTCUSDT,1575158405045139,1575158405045139,true,bid,7402.12,0.0015
binance,BTCUSDT,1575158405045139,1575158405045139,true,bid,7402,18.823628
binance,BTCUSDT,1575158405045139,1575158405045139,true,bid,7401.84,0.013838
binance,BTCUSDT,1575158405045139,1575158405045139,true,bid,7401.73,0.051136
binance,BTCUSDT,1575158405045139,1575158405045139,true,bid,7401.69,0.009914
binance,BTCUSDT,1575158405045139,1575158405045139,true,bid,7401.66,0.0023
binance,BTCUSDT,1575158405045139,1575158405045139,true,bid,7401.5,0.005527
binance,BTCUSDT,1575158405045139,1575158405045139,true,bid,7401.38,0.705552
binance,BTCUSDT,1575158405045139,1575158405045139,true,bid,7401.07,0.00179
binance,BTCUSDT,1575158405045139,1575158405045139,true,bid,7401.05,0.032528
binance,BTCUSDT,1575158405045139,1575158405045139,true,bid,7401,6.16014
binance,BTCUSDT,1575158405045139,1575158405045139,true,bid,7400.81,0.0051
binance,BTCUSDT,1575158405045139,1575158405045139,true,bid,7400.73,0.003504
binance,BTCUSDT,1575158405045139,1575158405045139,true,bid,7400.71,0.007205
binance,BTCUSDT,1575158405045139,1575158405045139,true,bid,7400.64,0.167561
binance,BTCUSDT,1575158405045139,1575158405045139,true,bid,7400.61,0.002479
binance,BTCUSDT,1575158405045139,1575158405045139,true,bid,7400.58,0.015347
binance,BTCUSDT,1575158405045139,1575158405045139,true,bid,7400.47,0.01352
binance,BTCUSDT,1575158405045139,1575158405045139,true,bid,7400.4,0.103446
binance,BTCUSDT,1575158405045139,1575158405045139,true,bid,7400.35,0.117264
binance,BTCUSDT,1575158405045139,1575158405045139,true,bid,7400.31,0.012758
binance,BTCUSDT,1575158405045139,1575158405045139,true,bid,7400.25,0.002333
binance,BTCUSDT,1575158405045139,1575158405045139,true,bid,7400.21,0.007395
binance,BTCUSDT,1575158405045139,1575158405045139,true,bid,7400.12,0.02
binance,BTCUSDT,1575158405045139,1575158405045139,true,bid,7400.11,0.010983
binance,BTCUSDT,1575158405045139,1575158405045139,true,bid,7400.09,0.2
binance,BTCUSDT,1575158405045139,1575158405045139,true,bid,7400.01,0.002298
binance,BTCUSDT,1575158405045139,1575158405045139,true,bid,7400,128.204155
binance,BTCUSDT,1575158405045139,1575158405045139,true,bid,7399.99,0.019743
binance,BTCUSDT,1575158405045139,1575158405045139,true,bid,7399.94,0.002
binance,BTCUSDT,1575158405045139,1575158405045139,true,bid,7399.51,0.008108
binance,BTCUSDT,1575158405045139,1575158405045139,true,bid,7399.47,0.00204
binance,BTCUSDT,1575158405045139,1575158405045139,true,bid,7399.09,0.001485
binance,BTCUSDT,1575158405045139,1575158405045139,true,bid,7399,0.297228
binance,BTCUSDT,1575158405045139,1575158405045139,true,bid,7398.99,0.020273
binance,BTCUSDT,1575158405045139,1575158405045139,true,bid,7398.93,0.002483
binance,BTCUSDT,1575158405045139,1575158405045139,true,bid,7398,0.014486
binance,BTCUSDT,1575158405045139,1575158405045139,true,bid,7397.95,0.082827
binance,BTCUSDT,1575158405045139,1575158405045139,true,bid,7397.88,0.182817
binance,BTCUSDT,1575158405045139,1575158405045139,true,bid,7397.71,0.0015
binance,BTCUSDT,1575158405045139,1575158405045139,true,bid,7397.46,0.002391
binance,BTCUSDT,1575158405045139,1575158405045139,true,bid,7397.09,0.001488
binance,BTCUSDT,1575158405045139,1575158405045139,true,bid,7396.85,0.161367
binance,BTCUSDT,1575158405045139,1575158405045139,true,bid,7396.16,0.242107
binance,BTCUSDT,1575158405045139,1575158405045139,true,bid,7396,0.001487
binance,BTCUSDT,1575158405045139,1575158405045139,true,bid,7395.91,0.001804
binance,BTCUSDT,1575158405045139,1575158405045139,true,bid,7395.59,0.061248
binance,BTCUSDT,1575158405045139,1575158405045139,true,bid,7395.21,0.002056
binance,BTCUSDT,1575158405045139,1575158405045139,true,bid,7395,0.911428
binance,BTCUSDT,1575158405045139,1575158405045139,true,bid,7394.73,0.00156
binance,BTCUSDT,1575158405045139,1575158405045139,true,bid,7394.07,0.001623
binance,BTCUSDT,1575158405045139,1575158405045139,true,bid,7394.03,0.018609
binance,BTCUSDT,1575158405045139,1575158405045139,true,bid,7394,2.843745
binance,BTCUSDT,1575158405045139,1575158405045139,true,bid,7393.79,0.001516
binance,BTCUSDT,1575158405045139,1575158405045139,true,bid,7393.65,0.002706
binance,BTCUSDT,1575158405045139,1575158405045139,true,bid,7393.44,0.004965
binance,BTCUSDT,1575158405045139,1575158405045139,true,bid,7393,0.010273
binance,BTCUSDT,1575158405045139,1575158405045139,true,bid,7392.89,0.001457
binance,BTCUSDT,1575158405045139,1575158405045139,true,bid,7392.4,0.00224
binance,BTCUSDT,1575158405045139,1575158405045139,true,bid,7392.3,0.096728
binance,BTCUSDT,1575158405045139,1575158405045139,true,bid,7392.2,2.326
binance,BTCUSDT,1575158405045139,1575158405045139,true,bid,7392,0.038259
binance,BTCUSDT,1575158405045139,1575158405045139,true,bid,7391.95,0.001646
binance,BTCUSDT,1575158405045139,1575158405045139,true,bid,7391.89,0.001611
binance,BTCUSDT,1575158405045139,1575158405045139,true,bid,7391.83,0.002331
binance,BTCUSDT,1575158405045139,1575158405045139,true,bid,7391.39,0.01353
binance,BTCUSDT,1575158405045139,1575158405045139,true,bid,7391.3,0.001516
binance,BTCUSDT,1575158405045139,1575158405045139,true,bid,7391,1.004281
binance,BTCUSDT,1575158405045139,1575158405045139,true,bid,7390.89,0.002484
binance,BTCUSDT,1575158405045139,1575158405045139,true,bid,7390.8,0.002373
binance,BTCUSDT,1575158405045139,1575158405045139,true,bid,7390.61,0.002704
binance,BTCUSDT,1575158405045139,1575158405045139,true,bid,7390.51,0.002207
binance,BTCUSDT,1575158405045139,1575158405045139,true,bid,7390.44,0.001443
binance,BTCUSDT,1575158405045139,1575158405045139,true,bid,7390.09,0.2
binance,BTCUSDT,1575158405045139,1575158405045139,true,bid,7390,22.87645
binance,BTCUSDT,1575158405045139,1575158405045139,true,bid,7389.49,0.002
binance,BTCUSDT,1575158405045139,1575158405045139,true,bid,7389.16,4.0679
binance,BTCUSDT,1575158405045139,1575158405045139,true,bid,7389,1.109297
binance,BTCUSDT,1575158405045139,1575158405045139,true,bid,7388.98,0.207999
binance,BTCUSDT,1575158405045139,1575158405045139,true,bid,7388.89,4.557944
binance,BTCUSDT,1575158405045139,1575158405045139,true,bid,7388.7,17.323374
binance,BTCUSDT,1575158405045139,1575158405045139,true,bid,7388.65,0.009078
binance,BTCUSDT,1575158405045139,1575158405045139,true,bid,7388.53,0.015552
binance,BTCUSDT,1575158405045139,1575158405045139,true,bid,7388.41,0.025
binance,BTCUSDT,1575158405045139,1575158405045139,true,bid,7388.31,0.002074
binance,BTCUSDT,1575158405045139,1575158405045139,true,bid,7388.21,0.0075
binance,BTCUSDT,1575158405045139,1575158405045139,true,bid,7388.07,0.2
binance,BTCUSDT,1575158405045139,1575158405045139,true,bid,7388.03,0.003563
binance,BTCUSDT,1575158405045139,1575158405045139,true,bid,7388,8.277335
binance,BTCUSDT,1575158405045139,1575158405045139,true,bid,7387.88,0.366129
binance,BTCUSDT,1575158405045139,1575158405045139,true,bid,7387.71,0.011396
binance,BTCUSDT,1575158405045139,1575158405045139,true,bid,7387.66,0.00164
binance,BTCUSDT,1575158405045139,1575158405045139,true,bid,7387.6,0.441732
binance,BTCUSDT,1575158405045139,1575158405045139,true,bid,7387.58,0.002716
binance,BTCUSDT,1575158405045139,1575158405045139,true,bid,7387.25,0.406376
binance,BTCUSDT,1575158405045139,1575158405045139,true,bid,7387.09,0.001443
binance,BTCUSDT,1575158405045139,1575158405045139,true,bid,7387.08,0.016289
binance,BTCUSDT,1575158405045139,1575158405045139,true,bid,7387,8.744174
binance,BTCUSDT,1575158405045139,1575158405045139,true,bid,7386.95,0.103214
binance,BTCUSDT,1575158405045139,1575158405045139,true,bid,7386.91,0.001488
binance,BTCUSDT,1575158405045139,1575158405045139,true,bid,7386.79,0.001704
binance,BTCUSDT,1575158405045139,1575158405045139,true,bid,7386.74,0.019268
binance,BTCUSDT,1575158405045139,1575158405045139,true,bid,7386.73,0.136408
binance,BTCUSDT,1575158405045139,1575158405045139,true,bid,7386.63,0.017024
binance,BTCUSDT,1575158405045139,1575158405045139,true,bid,7386.6,0.009726
binance,BTCUSDT,1575158405045139,1575158405045139,true,bid,7386.58,0.17035
binance,BTCUSDT,1575158405045139,1575158405045139,true,bid,7386.54,0.096632
binance,BTCUSDT,1575158405045139,1575158405045139,true,bid,7386.53,0.085177
binance,BTCUSDT,1575158405045139,1575158405045139,true,bid,7386.23,0.166651
binance,BTCUSDT,1575158405045139,1575158405045139,true,bid,7386.16,0.121218
binance,BTCUSDT,1575158405045139,1575158405045139,true,bid,7386.11,1.575417
binance,BTCUSDT,1575158405045139,1575158405045139,true,bid,7386.07,0.040149
binance,BTCUSDT,1575158405045139,1575158405045139,true,bid,7386.05,0.013526
binance,BTCUSDT,1575158405045139,1575158405045139,true,bid,7386,1.710362
binance,BTCUSDT,1575158405045139,1575158405045139,true,bid,7385.99,0.06818
binance,BTCUSDT,1575158405045139,1575158405045139,true,bid,7385.84,0.002632
binance,BTCUSDT,1575158405045139,1575158405045139,true,bid,7385.74,0.084808
binance,BTCUSDT,1575158405045139,1575158405045139,true,bid,7385.71,0.00143
binance,BTCUSDT,1575158405045139,1575158405045139,true,bid,7385.55,0.00136
binance,BTCUSDT,1575158405045139,1575158405045139,true,bid,7385.54,0.001614
binance,BTCUSDT,1575158405045139,1575158405045139,true,bid,7385.5,0.001624
binance,BTCUSDT,1575158405045139,1575158405045139,true,bid,7385.41,0.406411
binance,BTCUSDT,1575158405045139,1575158405045139,true,bid,7385.34,2
binance,BTCUSDT,1575158405045139,1575158405045139,true,bid,7385.31,0.001566
binance,BTCUSDT,1575158405045139,1575158405045139,true,bid,7385,8.135005
binance,BTCUSDT,1575158405045139,1575158405045139,true,bid,7384.73,0.002844
binance,BTCUSDT,1575158405045139,1575158405045139,true,bid,7384.61,0.009709
binance,BTCUSDT,1575158405045139,1575158405045139,true,bid,7384.55,0.503
binance,BTCUSDT,1575158405045139,1575158405045139,true,bid,7384.5,0.003888
binance,BTCUSDT,1575158405045139,1575158405045139,true,bid,7384.4,0.009256
binance,BTCUSDT,1575158405045139,1575158405045139,true,bid,7384.04,0.032838
binance,BTCUSDT,1575158405045139,1575158405045139,true,bid,7384,0.006395
binance,BTCUSDT,1575158405045139,1575158405045139,true,bid,7383.33,0.007053
binance,BTCUSDT,1575158405045139,1575158405045139,true,bid,7383.01,0.00148
binance,BTCUSDT,1575158405045139,1575158405045139,true,bid,7383,0.125445
binance,BTCUSDT,1575158405045139,1575158405045139,true,bid,7382.75,0.062104
binance,BTCUSDT,1575158405045139,1575158405045139,true,bid,7382.72,0.001783
binance,BTCUSDT,1575158405045139,1575158405045139,true,bid,7382.7,0.039628
binance,BTCUSDT,1575158405045139,1575158405045139,true,bid,7382.65,0.042827
binance,BTCUSDT,1575158405045139,1575158405045139,true,bid,7382.26,0.006773
binance,BTCUSDT,1575158405045139,1575158405045139,true,bid,7382.2,2.326
binance,BTCUSDT,1575158405045139,1575158405045139,true,bid,7382.1,0.005
binance,BTCUSDT,1575158405045139,1575158405045139,true,bid,7382,4.834191
binance,BTCUSDT,1575158405045139,1575158405045139,true,bid,7381.9,0.002903
binance,BTCUSDT,1575158405045139,1575158405045139,true,bid,7381.87,0.08509
binance,BTCUSDT,1575158405045139,1575158405045139,true,bid,7381.81,0.10138
binance,BTCUSDT,1575158405045139,1575158405045139,true,bid,7381.8,2.045857
binance,BTCUSDT,1575158405045139,1575158405045139,true,bid,7381.72,0.001902
binance,BTCUSDT,1575158405045139,1575158405045139,true,bid,7381.69,0.003967
binance,BTCUSDT,1575158405045139,1575158405045139,true,bid,7381.62,0.08836
binance,BTCUSDT,1575158405045139,1575158405045139,true,bid,7381.35,0.056344
binance,BTCUSDT,1575158405045139,1575158405045139,true,bid,7381.24,0.359678
binance,BTCUSDT,1575158405045139,1575158405045139,true,bid,7381,0.646589
binance,BTCUSDT,1575158405045139,1575158405045139,true,bid,7380.95,0.012767
binance,BTCUSDT,1575158405045139,1575158405045139,true,bid,7380.77,0.297796
binance,BTCUSDT,1575158405045139,1575158405045139,true,bid,7380.5,0.003775
binance,BTCUSDT,1575158405045139,1575158405045139,true,bid,7380.23,0.125104
binance,BTCUSDT,1575158405045139,1575158405045139,true,bid,7380.14,0.011029
binance,BTCUSDT,1575158405045139,1575158405045139,true,bid,7380.09,0.2
binance,BTCUSDT,1575158405045139,1575158405045139,true,bid,7380.01,5.855907
binance,BTCUSDT,1575158405045139,1575158405045139,true,bid,7380,9.918713
binance,BTCUSDT,1575158405045139,1575158405045139,true,bid,7379.74,0.025323
binance,BTCUSDT,1575158405045139,1575158405045139,true,bid,7379.66,0.01355
binance,BTCUSDT,1575158405045139,1575158405045139,true,bid,7379.42,0.004841
binance,BTCUSDT,1575158405045139,1575158405045139,true,bid,7379.37,0.001626
binance,BTCUSDT,1575158405045139,1575158405045139,true,bid,7379.17,0.008076
binance,BTCUSDT,1575158405045139,1575158405045139,true,bid,7379.04,0.036006
binance,BTCUSDT,1575158405045139,1575158405045139,true,bid,7379,5.756311
binance,BTCUSDT,1575158405045139,1575158405045139,true,bid,7378.54,0.006776
binance,BTCUSDT,1575158405045139,1575158405045139,true,bid,7378.25,0.381112
binance,BTCUSDT,1575158405045139,1575158405045139,true,bid,7378.1,0.002603
binance,BTCUSDT,1575158405045139,1575158405045139,true,bid,7378.06,0.048675
binance,BTCUSDT,1575158405045139,1575158405045139,true,bid,7378,2.54634
binance,BTCUSDT,1575158405045139,1575158405045139,true,bid,7377.88,0.244416
binance,BTCUSDT,1575158405045139,1575158405045139,true,bid,7377.53,0.006758
binance,BTCUSDT,1575158405045139,1575158405045139,true,bid,7377.12,0.009
binance,BTCUSDT,1575158405045139,1575158405045139,true,bid,7377.04,0.039037
binance,BTCUSDT,1575158405045139,1575158405045139,true,bid,7377,3.751326
binance,BTCUSDT,1575158405045139,1575158405045139,true,bid,7376.83,0.0023
binance,BTCUSDT,1575158405045139,1575158405045139,true,bid,7376.73,0.04879
binance,BTCUSDT,1575158405045139,1575158405045139,true,bid,7376.66,0.03
binance,BTCUSDT,1575158405045139,1575158405045139,true,bid,7376.4,0.028333
binance,BTCUSDT,1575158405045139,1575158405045139,true,bid,7376.37,0.089592
binance,BTCUSDT,1575158405045139,1575158405045139,true,bid,7376.18,0.001356
binance,BTCUSDT,1575158405045139,1575158405045139,true,bid,7376.04,0.002005
binance,BTCUSDT,1575158405045139,1575158405045139,true,bid,7376,1.515821
binance,BTCUSDT,1575158405045139,1575158405045139,true,bid,7375.92,0.002978
binance,BTCUSDT,1575158405045139,1575158405045139,true,bid,7375.83,0.092987
binance,BTCUSDT,1575158405045139,1575158405045139,true,bid,7375.79,0.015147
binance,BTCUSDT,1575158405045139,1575158405045139,true,bid,7375.25,0.00678
binance,BTCUSDT,1575158405045139,1575158405045139,true,bid,7375.03,17.81
binance,BTCUSDT,1575158405045139,1575158405045139,true,bid,7375.01,0.027655
binance,BTCUSDT,1575158405045139,1575158405045139,true,bid,7375,8.869639
binance,BTCUSDT,1575158405045139,1575158405045139,true,bid,7374.93,0.001653
binance,BTCUSDT,1575158405045139,1575158405045139,true,bid,7374.11,0.032284
binance,BTCUSDT,1575158405045139,1575158405045139,true,bid,7374,0.351837
binance,BTCUSDT,1575158405045139,1575158405045139,true,bid,7373.85,0.0015
binance,BTCUSDT,1575158405045139,1575158405045139,true,bid,7373.51,0.138116
binance,BTCUSDT,1575158405045139,1575158405045139,true,bid,7373.28,1
binance,BTCUSDT,1575158405045139,1575158405045139,true,bid,7373,2.039758
binance,BTCUSDT,1575158405045139,1575158405045139,true,bid,7372.94,0.013564
binance,BTCUSDT,1575158405045139,1575158405045139,true,bid,7372.91,0.001817
binance,BTCUSDT,1575158405045139,1575158405045139,true,bid,7372.72,0.013564
binance,BTCUSDT,1575158405045139,1575158405045139,true,bid,7372.7,0.013564
binance,BTCUSDT,1575158405045139,1575158405045139,true,bid,7372.61,0.005809
binance,BTCUSDT,1575158405045139,1575158405045139,true,bid,7372.59,0.001483
binance,BTCUSDT,1575158405045139,1575158405045139,true,bid,7372.51,0.00177
binance,BTCUSDT,1575158405045139,1575158405045139,true,bid,7372.2,2.326
binance,BTCUSDT,1575158405045139,1575158405045139,true,bid,7372.03,0.00734
binance,BTCUSDT,1575158405045139,1575158405045139,true,bid,7372,0.105403
binance,BTCUSDT,1575158405045139,1575158405045139,true,bid,7371.67,0.003005
binance,BTCUSDT,1575158405045139,1575158405045139,true,bid,7371.63,0.013467
binance,BTCUSDT,1575158405045139,1575158405045139,true,bid,7371.2,0.001807
binance,BTCUSDT,1575158405045139,1575158405045139,true,bid,7371.14,0.001648
binance,BTCUSDT,1575158405045139,1575158405045139,true,bid,7371,0.25
binance,BTCUSDT,1575158405045139,1575158405045139,true,bid,7370.76,0.5
binance,BTCUSDT,1575158405045139,1575158405045139,true,bid,7370.72,0.001457
binance,BTCUSDT,1575158405045139,1575158405045139,true,bid,7370.6,4.030456
binance,BTCUSDT,1575158405045139,1575158405045139,true,bid,7370.26,0.068184
binance,BTCUSDT,1575158405045139,1575158405045139,true,bid,7370.06,0.003596
binance,BTCUSDT,1575158405045139,1575158405045139,true,bid,7370.02,0.061955
binance,BTCUSDT,1575158405045139,1575158405045139,true,bid,7370,10.361435
binance,BTCUSDT,1575158405045139,1575158405045139,true,bid,7369.89,0.339218
binance,BTCUSDT,1575158405045139,1575158405045139,true,bid,7369.87,0.002048
binance,BTCUSDT,1575158405045139,1575158405045139,true,bid,7369.75,0.001806
binance,BTCUSDT,1575158405045139,1575158405045139,true,bid,7369.71,0.00273
binance,BTCUSDT,1575158405045139,1575158405045139,true,bid,7369.5,0.001602
binance,BTCUSDT,1575158405045139,1575158405045139,true,bid,7369.3,0.002649
binance,BTCUSDT,1575158405045139,1575158405045139,true,bid,7369.23,0.096728
binance,BTCUSDT,1575158405045139,1575158405045139,true,bid,7369.21,0.023682
binance,BTCUSDT,1575158405045139,1575158405045139,true,bid,7369.2,0.403649
binance,BTCUSDT,1575158404999000,1575158405116597,false,bid,7537.42,0.2
binance,BTCUSDT,1575158404999000,1575158405116597,false,bid,7523.16,0.056039
binance,BTCUSDT,1575158405098000,1575158405215664,false,ask,7549.86,0.397362
binance,BTCUSDT,1575158405098000,1575158405215664,false,ask,7555.33,0.010609
binance,BTCUSDT,1575158405098000,1575158405215664,false,ask,7558.04,0
binance,BTCUSDT,1575158405098000,1575158405215664,false,bid,7490.83,0
binance,BTCUSDT,1575158405198000,1575158405315841,false,ask,7541.48,2.15936
binance,BTCUSDT,1575158405198000,1575158405315841,false,ask,7541.9,0
binance,BTCUSDT,1575158405198000,1575158405315841,false,ask,7564.94,0.534392
binance,BTCUSDT,1575158405198000,1575158405315841,false,ask,7570.29,0
binance,BTCUSDT,1575158405198000,1575158405315841,false,bid,7534.93,0
binance,BTCUSDT,1575158405298000,1575158405415810,false,ask,7541.36,0.045141
binance,BTCUSDT,1575158405298000,1575158405415810,false,ask,7541.87,0
binance,BTCUSDT,1575158405298000,1575158405415810,false,ask,7547.18,0.059625
binance,BTCUSDT,1575158405298000,1575158405415810,false,ask,7550.08,0.030186
binance,BTCUSDT,1575158405298000,1575158405415810,false,ask,7580,7.082538
binance,BTCUSDT,1575158405298000,1575158405415810,false,ask,7582.62,0.006625
binance,BTCUSDT,1575158405298000,1575158405415810,false,ask,7614.84,0.030146
binance,BTCUSDT,1575158405298000,1575158405415810,false,bid,7483.05,0.467723
binance,BTCUSDT,1575158405398000,1575158405515803,false,ask,7541.35,0.385806
binance,BTCUSDT,1575158405398000,1575158405515803,false,ask,7541.36,0.059183
binance,BTCUSDT,1575158405398000,1575158405515803,false,ask,7541.38,0
binance,BTCUSDT,1575158405398000,1575158405515803,false,ask,7541.39,0
binance,BTCUSDT,1575158405398000,1575158405515803,false,ask,7541.49,0
binance,BTCUSDT,1575158405398000,1575158405515803,false,ask,7541.85,0
binance,BTCUSDT,1575158405398000,1575158405515803,false,ask,7546.52,0.036185
binance,BTCUSDT,1575158405398000,1575158405515803,false,ask,7547.74,0
binance,BTCUSDT,1575158405398000,1575158405515803,false,bid,7538.47,0
binance,BTCUSDT,1575158405398000,1575158405515803,false,bid,7538.23,0
binance,BTCUSDT,1575158405398000,1575158405515803,false,bid,7537.74,0.3
binance,BTCUSDT,1575158405398000,1575158405515803,false,bid,7534.41,0.29806
binance,BTCUSDT,1575158405398000,1575158405515803,false,bid,7264.55,0.002
binance,BTCUSDT,1575158405498000,1575158405616000,false,ask,7541.32,0.017977
binance,BTCUSDT,1575158405498000,1575158405616000,false,ask,7541.33,0.3
binance,BTCUSDT,1575158405498000,1575158405616000,false,ask,7541.34,0
binance,BTCUSDT,1575158405498000,1575158405616000,false,ask,7541.35,0
binance,BTCUSDT,1575158405498000,1575158405616000,false,ask,7541.36,0.045141
binance,BTCUSDT,1575158405498000,1575158405616000,false,ask,7542.4,0.5
binance,BTCUSDT,1575158405498000,1575158405616000,false,ask,7542.43,0.5
binance,BTCUSDT,1575158405498000,1575158405616000,false,ask,7542.85,0
binance,BTCUSDT,1575158405498000,1575158405616000,false,ask,7543.44,0
binance,BTCUSDT,1575158405498000,1575158405616000,false,ask,7545.08,0.088098
binance,BTCUSDT,1575158405498000,1575158405616000,false,ask,7545.17,0
binance,BTCUSDT,1575158405498000,1575158405616000,false,ask,7548.53,0
binance,BTCUSDT,1575158405498000,1575158405616000,false,ask,7550,0.711364
binance,BTCUSDT,1575158405498000,1575158405616000,false,bid,7480,22.517448
binance,BTCUSDT,1575158405598000,1575158405716112,false,ask,7541.27,0.260806
binance,BTCUSDT,1575158405598000,1575158405716112,false,ask,7541.28,0.017977
binance,BTCUSDT,1575158405598000,1575158405716112,false,ask,7541.29,0
binance,BTCUSDT,1575158405598000,1575158405716112,false,ask,7541.3,0
